Workbook

Sheet Summary
A1: SUMMARY | B1: DTO | C1: VALUE | D1: REJ DTO | E1: REJ VALUE | H1: MONTH SUMMARY | I1: REC DTO | J1: VALUE | K1: REJ DTO | L1: REJ VALUE | M1: ACC DTO2 | N1: ACC VALUE
A2: 46023 | B2: =ACU!D3+AIB!D3+ARC!D3+AXS!D3+BOU!D3+BPO!D3+CSS!D3+MAM!D3+MED!D3+MEM!D3+MKT!D3+MTS!D3+NAV!D3+'NUM{THR}'!D3+PAR!D3+RAN!D3+RCO!D3+SA!D3+TFG!D3+TLD!D3 -> 0 | C2: =ACU!E3+AIB!E3+ARC!E3+AXS!E3+BOU!E3+BPO!E3+CSS!E3+MAM!E3+MED!E3+MEM!E3+MKT!E3+MTS!E3+NAV!E3+'NUM{THR}'!E3+PAR!E3+RAN!E3+RCO!E3+SA!E3+TFG!E3+TLD!E3 -> 0 | D2: =ACU!F3+AIB!F3+ARC!F3+AXS!F3+BOU!F3+BPO!F3+CSS!F3+MAM!F3+MED!F3+MEM!F3+MKT!F3+MTS!F3+NAV!F3+'NUM{THR}'!F3+PAR!F3+RAN!F3+RCO!F3+SA!F3+TFG!F3+TLD!F3 -> 0 | E2: =ACU!G3+AIB!G3+ARC!G3+AXS!G3+BOU!G3+BPO!G3+CSS!G3+MAM!G3+MED!G3+MEM!G3+MKT!G3+MTS!G3+NAV!G3+'NUM{THR}'!G3+PAR!G3+RAN!G3+RCO!G3+SA!G3+TFG!G3+TLD!G3 -> 0 | H2: ACU | I2: =ACU!D1 -> 1 | J2: =ACU!E1 -> 578 | K2: =ACU!F1 -> 0 | L2: =ACU!G1 -> 0 | M2: =ACU!H1 -> 1 | N2: =ACU!I1 -> 578
A3: 46024 | B3: =ACU!D4+AIB!D4+ARC!D4+AXS!D4+BOU!D4+BPO!D4+CSS!D4+MAM!D4+MED!D4+MEM!D4+MKT!D4+MTS!D4+NAV!D4+'NUM{THR}'!D4+PAR!D4+RAN!D4+RCO!D4+SA!D4+TFG!D4+TLD!D4 -> 692 | C3: =ACU!E4+AIB!E4+ARC!E4+AXS!E4+BOU!E4+BPO!E4+CSS!E4+MAM!E4+MED!E4+MEM!E4+MKT!E4+MTS!E4+NAV!E4+'NUM{THR}'!E4+PAR!E4+RAN!E4+RCO!E4+SA!E4+TFG!E4+TLD!E4 -> 719306 | D3: =ACU!F4+AIB!F4+ARC!F4+AXS!F4+BOU!F4+BPO!F4+CSS!F4+MAM!F4+MED!F4+MEM!F4+MKT!F4+MTS!F4+NAV!F4+'NUM{THR}'!F4+PAR!F4+RAN!F4+RCO!F4+SA!F4+TFG!F4+TLD!F4 -> 0 | E3: =ACU!G4+AIB!G4+ARC!G4+AXS!G4+BOU!G4+BPO!G4+CSS!G4+MAM!G4+MED!G4+MEM!G4+MKT!G4+MTS!G4+NAV!G4+'NUM{THR}'!G4+PAR!G4+RAN!G4+RCO!G4+SA!G4+TFG!G4+TLD!G4 -> 0 | H3: AIB | I3: =AIB!D1 -> 12 | J3: =AIB!E1 -> 9589 | K3: =AIB!F1 -> 0 | L3: =AIB!G1 -> 0 | M3: =AIB!H1 -> 12 | N3: =AIB!I1 -> 9589
A4: 46025 | B4: =ACU!D5+AIB!D5+ARC!D5+AXS!D5+BOU!D5+BPO!D5+CSS!D5+MAM!D5+MED!D5+MEM!D5+MKT!D5+MTS!D5+NAV!D5+'NUM{THR}'!D5+PAR!D5+RAN!D5+RCO!D5+SA!D5+TFG!D5+TLD!D5 -> 54 | C4: =ACU!E5+AIB!E5+ARC!E5+AXS!E5+BOU!E5+BPO!E5+CSS!E5+MAM!E5+MED!E5+MEM!E5+MKT!E5+MTS!E5+NAV!E5+'NUM{THR}'!E5+PAR!E5+RAN!E5+RCO!E5+SA!E5+TFG!E5+TLD!E5 -> 60182 | D4: =ACU!F5+AIB!F5+ARC!F5+AXS!F5+BOU!F5+BPO!F5+CSS!F5+MAM!F5+MED!F5+MEM!F5+MKT!F5+MTS!F5+NAV!F5+'NUM{THR}'!F5+PAR!F5+RAN!F5+RCO!F5+SA!F5+TFG!F5+TLD!F5 -> 0 | E4: =ACU!G5+AIB!G5+ARC!G5+AXS!G5+BOU!G5+BPO!G5+CSS!G5+MAM!G5+MED!G5+MEM!G5+MKT!G5+MTS!G5+NAV!G5+'NUM{THR}'!G5+PAR!G5+RAN!G5+RCO!G5+SA!G5+TFG!G5+TLD!G5 -> 0 | H4: ARC | I4: =ARC!D1 -> 16 | J4: =ARC!E1 -> 18078 | K4: =ARC!F1 -> 0 | L4: =ARC!G1 -> 0 | M4: =ARC!H1 -> 16 | N4: =ARC!I1 -> 18078
A5: 46026 | B5: =ACU!D6+AIB!D6+ARC!D6+AXS!D6+BOU!D6+BPO!D6+CSS!D6+MAM!D6+MED!D6+MEM!D6+MKT!D6+MTS!D6+NAV!D6+'NUM{THR}'!D6+PAR!D6+RAN!D6+RCO!D6+SA!D6+TFG!D6+TLD!D6 -> 0 | C5: =ACU!E6+AIB!E6+ARC!E6+AXS!E6+BOU!E6+BPO!E6+CSS!E6+MAM!E6+MED!E6+MEM!E6+MKT!E6+MTS!E6+NAV!E6+'NUM{THR}'!E6+PAR!E6+RAN!E6+RCO!E6+SA!E6+TFG!E6+TLD!E6 -> 0 | D5: =ACU!F6+AIB!F6+ARC!F6+AXS!F6+BOU!F6+BPO!F6+CSS!F6+MAM!F6+MED!F6+MEM!F6+MKT!F6+MTS!F6+NAV!F6+'NUM{THR}'!F6+PAR!F6+RAN!F6+RCO!F6+SA!F6+TFG!F6+TLD!F6 -> 0 | E5: =ACU!G6+AIB!G6+ARC!G6+AXS!G6+BOU!G6+BPO!G6+CSS!G6+MAM!G6+MED!G6+MEM!G6+MKT!G6+MTS!G6+NAV!G6+'NUM{THR}'!G6+PAR!G6+RAN!G6+RCO!G6+SA!G6+TFG!G6+TLD!G6 -> 0 | H5: AXS | I5: =AXS!D1 -> 15 | J5: =AXS!E1 -> 11591 | K5: =AXS!F1 -> 0 | L5: =AXS!G1 -> 0 | M5: =AXS!H1 -> 15 | N5: =AXS!I1 -> 11591
A6: 46027 | B6: =ACU!D7+AIB!D7+ARC!D7+AXS!D7+BOU!D7+BPO!D7+CSS!D7+MAM!D7+MED!D7+MEM!D7+MKT!D7+MTS!D7+NAV!D7+'NUM{THR}'!D7+PAR!D7+RAN!D7+RCO!D7+SA!D7+TFG!D7+TLD!D7 -> 77 | C6: =ACU!E7+AIB!E7+ARC!E7+AXS!E7+BOU!E7+BPO!E7+CSS!E7+MAM!E7+MED!E7+MEM!E7+MKT!E7+MTS!E7+NAV!E7+'NUM{THR}'!E7+PAR!E7+RAN!E7+RCO!E7+SA!E7+TFG!E7+TLD!E7 -> 77119 | D6: =ACU!F7+AIB!F7+ARC!F7+AXS!F7+BOU!F7+BPO!F7+CSS!F7+MAM!F7+MED!F7+MEM!F7+MKT!F7+MTS!F7+NAV!F7+'NUM{THR}'!F7+PAR!F7+RAN!F7+RCO!F7+SA!F7+TFG!F7+TLD!F7 -> 0 | E6: =ACU!G7+AIB!G7+ARC!G7+AXS!G7+BOU!G7+BPO!G7+CSS!G7+MAM!G7+MED!G7+MEM!G7+MKT!G7+MTS!G7+NAV!G7+'NUM{THR}'!G7+PAR!G7+RAN!G7+RCO!G7+SA!G7+TFG!G7+TLD!G7 -> 0 | H6: BOU | I6: =BOU!D1 -> 2 | J6: =BOU!E1 -> 1560 | K6: =BOU!F1 -> 0 | L6: =BOU!G1 -> 0 | M6: =BOU!H1 -> 2 | N6: =BOU!I1 -> 1560
A7: 46028 | B7: =ACU!D8+AIB!D8+ARC!D8+AXS!D8+BOU!D8+BPO!D8+CSS!D8+MAM!D8+MED!D8+MEM!D8+MKT!D8+MTS!D8+NAV!D8+'NUM{THR}'!D8+PAR!D8+RAN!D8+RCO!D8+SA!D8+TFG!D8+TLD!D8 -> 19 | C7: =ACU!E8+AIB!E8+ARC!E8+AXS!E8+BOU!E8+BPO!E8+CSS!E8+MAM!E8+MED!E8+MEM!E8+MKT!E8+MTS!E8+NAV!E8+'NUM{THR}'!E8+PAR!E8+RAN!E8+RCO!E8+SA!E8+TFG!E8+TLD!E8 -> 17218 | D7: =ACU!F8+AIB!F8+ARC!F8+AXS!F8+BOU!F8+BPO!F8+CSS!F8+MAM!F8+MED!F8+MEM!F8+MKT!F8+MTS!F8+NAV!F8+'NUM{THR}'!F8+PAR!F8+RAN!F8+RCO!F8+SA!F8+TFG!F8+TLD!F8 -> 0 | E7: =ACU!G8+AIB!G8+ARC!G8+AXS!G8+BOU!G8+BPO!G8+CSS!G8+MAM!G8+MED!G8+MEM!G8+MKT!G8+MTS!G8+NAV!G8+'NUM{THR}'!G8+PAR!G8+RAN!G8+RCO!G8+SA!G8+TFG!G8+TLD!G8 -> 0 | H7: BPO | I7: =BPO!D1 -> 6 | J7: =BPO!E1 -> 6302 | K7: =BPO!F1 -> 0 | L7: =BPO!G1 -> 0 | M7: =BPO!H1 -> 6 | N7: =BPO!I1 -> 6302
A8: 46029 | B8: =ACU!D9+AIB!D9+ARC!D9+AXS!D9+BOU!D9+BPO!D9+CSS!D9+MAM!D9+MED!D9+MEM!D9+MKT!D9+MTS!D9+NAV!D9+'NUM{THR}'!D9+PAR!D9+RAN!D9+RCO!D9+SA!D9+TFG!D9+TLD!D9 -> 97 | C8: =ACU!E9+AIB!E9+ARC!E9+AXS!E9+BOU!E9+BPO!E9+CSS!E9+MAM!E9+MED!E9+MEM!E9+MKT!E9+MTS!E9+NAV!E9+'NUM{THR}'!E9+PAR!E9+RAN!E9+RCO!E9+SA!E9+TFG!E9+TLD!E9 -> 100905 | D8: =ACU!F9+AIB!F9+ARC!F9+AXS!F9+BOU!F9+BPO!F9+CSS!F9+MAM!F9+MED!F9+MEM!F9+MKT!F9+MTS!F9+NAV!F9+'NUM{THR}'!F9+PAR!F9+RAN!F9+RCO!F9+SA!F9+TFG!F9+TLD!F9 -> 0 | E8: =ACU!G9+AIB!G9+ARC!G9+AXS!G9+BOU!G9+BPO!G9+CSS!G9+MAM!G9+MED!G9+MEM!G9+MKT!G9+MTS!G9+NAV!G9+'NUM{THR}'!G9+PAR!G9+RAN!G9+RCO!G9+SA!G9+TFG!G9+TLD!G9 -> 0 | H8: CSS | I8: =CSS!D1 -> 2 | J8: =CSS!E1 -> 1055 | K8: =CSS!F1 -> 0 | L8: =CSS!G1 -> 0 | M8: =CSS!H1 -> 2 | N8: =CSS!I1 -> 1055
A9: 46030 | B9: =ACU!D10+AIB!D10+ARC!D10+AXS!D10+BOU!D10+BPO!D10+CSS!D10+MAM!D10+MED!D10+MEM!D10+MKT!D10+MTS!D10+NAV!D10+'NUM{THR}'!D10+PAR!D10+RAN!D10+RCO!D10+SA!D10+TFG!D10+TLD!D10 -> 5 | C9: =ACU!E10+AIB!E10+ARC!E10+AXS!E10+BOU!E10+BPO!E10+CSS!E10+MAM!E10+MED!E10+MEM!E10+MKT!E10+MTS!E10+NAV!E10+'NUM{THR}'!E10+PAR!E10+RAN!E10+RCO!E10+SA!E10+TFG!E10+TLD!E10 -> 4411 | D9: =ACU!F10+AIB!F10+ARC!F10+AXS!F10+BOU!F10+BPO!F10+CSS!F10+MAM!F10+MED!F10+MEM!F10+MKT!F10+MTS!F10+NAV!F10+'NUM{THR}'!F10+PAR!F10+RAN!F10+RCO!F10+SA!F10+TFG!F10+TLD!F10 -> 0 | E9: =ACU!G10+AIB!G10+ARC!G10+AXS!G10+BOU!G10+BPO!G10+CSS!G10+MAM!G10+MED!G10+MEM!G10+MKT!G10+MTS!G10+NAV!G10+'NUM{THR}'!G10+PAR!G10+RAN!G10+RCO!G10+SA!G10+TFG!G10+TLD!G10 -> 0 | H9: MAM | I9: =MAM!D1 -> 163 | J9: =MAM!E1 -> 161530.25 | K9: =MAM!F1 -> 0 | L9: =MAM!G1 -> 0 | M9: =MAM!H1 -> 163 | N9: =MAM!I1 -> 161530.25
A10: 46031 | B10: =ACU!D11+AIB!D11+ARC!D11+AXS!D11+BOU!D11+BPO!D11+CSS!D11+MAM!D11+MED!D11+MEM!D11+MKT!D11+MTS!D11+NAV!D11+'NUM{THR}'!D11+PAR!D11+RAN!D11+RCO!D11+SA!D11+TFG!D11+TLD!D11 -> 1 | C10: =ACU!E11+AIB!E11+ARC!E11+AXS!E11+BOU!E11+BPO!E11+CSS!E11+MAM!E11+MED!E11+MEM!E11+MKT!E11+MTS!E11+NAV!E11+'NUM{THR}'!E11+PAR!E11+RAN!E11+RCO!E11+SA!E11+TFG!E11+TLD!E11 -> 985 | D10: =ACU!F11+AIB!F11+ARC!F11+AXS!F11+BOU!F11+BPO!F11+CSS!F11+MAM!F11+MED!F11+MEM!F11+MKT!F11+MTS!F11+NAV!F11+'NUM{THR}'!F11+PAR!F11+RAN!F11+RCO!F11+SA!F11+TFG!F11+TLD!F11 -> 0 | E10: =ACU!G11+AIB!G11+ARC!G11+AXS!G11+BOU!G11+BPO!G11+CSS!G11+MAM!G11+MED!G11+MEM!G11+MKT!G11+MTS!G11+NAV!G11+'NUM{THR}'!G11+PAR!G11+RAN!G11+RCO!G11+SA!G11+TFG!G11+TLD!G11 -> 0 | H10: MED | I10: =MED!D1 -> 54 | J10: =MED!E1 -> 48188.75 | K10: =MED!F1 -> 0 | L10: =MED!G1 -> 0 | M10: =MED!H1 -> 54 | N10: =MED!I1 -> 48188.75
A11: 46032 | B11: =ACU!D12+AIB!D12+ARC!D12+AXS!D12+BOU!D12+BPO!D12+CSS!D12+MAM!D12+MED!D12+MEM!D12+MKT!D12+MTS!D12+NAV!D12+'NUM{THR}'!D12+PAR!D12+RAN!D12+RCO!D12+SA!D12+TFG!D12+TLD!D12 -> 14 | C11: =ACU!E12+AIB!E12+ARC!E12+AXS!E12+BOU!E12+BPO!E12+CSS!E12+MAM!E12+MED!E12+MEM!E12+MKT!E12+MTS!E12+NAV!E12+'NUM{THR}'!E12+PAR!E12+RAN!E12+RCO!E12+SA!E12+TFG!E12+TLD!E12 -> 16743.5 | D11: =ACU!F12+AIB!F12+ARC!F12+AXS!F12+BOU!F12+BPO!F12+CSS!F12+MAM!F12+MED!F12+MEM!F12+MKT!F12+MTS!F12+NAV!F12+'NUM{THR}'!F12+PAR!F12+RAN!F12+RCO!F12+SA!F12+TFG!F12+TLD!F12 -> 0 | E11: =ACU!G12+AIB!G12+ARC!G12+AXS!G12+BOU!G12+BPO!G12+CSS!G12+MAM!G12+MED!G12+MEM!G12+MKT!G12+MTS!G12+NAV!G12+'NUM{THR}'!G12+PAR!G12+RAN!G12+RCO!G12+SA!G12+TFG!G12+TLD!G12 -> 0 | H11: MEM | I11: =MEM!D1 -> 56 | J11: =MEM!E1 -> 52231 | K11: =MEM!F1 -> 0 | L11: =MEM!G1 -> 0 | M11: =MEM!H1 -> 56 | N11: =MEM!I1 -> 52231
A12: 46033 | B12: =ACU!D13+AIB!D13+ARC!D13+AXS!D13+BOU!D13+BPO!D13+CSS!D13+MAM!D13+MED!D13+MEM!D13+MKT!D13+MTS!D13+NAV!D13+'NUM{THR}'!D13+PAR!D13+RAN!D13+RCO!D13+SA!D13+TFG!D13+TLD!D13 -> 0 | C12: =ACU!E13+AIB!E13+ARC!E13+AXS!E13+BOU!E13+BPO!E13+CSS!E13+MAM!E13+MED!E13+MEM!E13+MKT!E13+MTS!E13+NAV!E13+'NUM{THR}'!E13+PAR!E13+RAN!E13+RCO!E13+SA!E13+TFG!E13+TLD!E13 -> 0 | D12: =ACU!F13+AIB!F13+ARC!F13+AXS!F13+BOU!F13+BPO!F13+CSS!F13+MAM!F13+MED!F13+MEM!F13+MKT!F13+MTS!F13+NAV!F13+'NUM{THR}'!F13+PAR!F13+RAN!F13+RCO!F13+SA!F13+TFG!F13+TLD!F13 -> 0 | E12: =ACU!G13+AIB!G13+ARC!G13+AXS!G13+BOU!G13+BPO!G13+CSS!G13+MAM!G13+MED!G13+MEM!G13+MKT!G13+MTS!G13+NAV!G13+'NUM{THR}'!G13+PAR!G13+RAN!G13+RCO!G13+SA!G13+TFG!G13+TLD!G13 -> 0 | H12: MKT | I12: =MKT!D1 -> 17 | J12: =MKT!E1 -> 16844.75 | K12: =MKT!F1 -> 0 | L12: =MKT!G1 -> 0 | M12: =MKT!H1 -> 17 | N12: =MKT!I1 -> 16844.75
A13: 46034 | B13: =ACU!D14+AIB!D14+ARC!D14+AXS!D14+BOU!D14+BPO!D14+CSS!D14+MAM!D14+MED!D14+MEM!D14+MKT!D14+MTS!D14+NAV!D14+'NUM{THR}'!D14+PAR!D14+RAN!D14+RCO!D14+SA!D14+TFG!D14+TLD!D14 -> 7 | C13: =ACU!E14+AIB!E14+ARC!E14+AXS!E14+BOU!E14+BPO!E14+CSS!E14+MAM!E14+MED!E14+MEM!E14+MKT!E14+MTS!E14+NAV!E14+'NUM{THR}'!E14+PAR!E14+RAN!E14+RCO!E14+SA!E14+TFG!E14+TLD!E14 -> 6697 | D13: =ACU!F14+AIB!F14+ARC!F14+AXS!F14+BOU!F14+BPO!F14+CSS!F14+MAM!F14+MED!F14+MEM!F14+MKT!F14+MTS!F14+NAV!F14+'NUM{THR}'!F14+PAR!F14+RAN!F14+RCO!F14+SA!F14+TFG!F14+TLD!F14 -> 0 | E13: =ACU!G14+AIB!G14+ARC!G14+AXS!G14+BOU!G14+BPO!G14+CSS!G14+MAM!G14+MED!G14+MEM!G14+MKT!G14+MTS!G14+NAV!G14+'NUM{THR}'!G14+PAR!G14+RAN!G14+RCO!G14+SA!G14+TFG!G14+TLD!G14 -> 0 | H13: MTS | I13: =MTS!D1 -> 6 | J13: =MTS!E1 -> 3729 | K13: =MTS!F1 -> 0 | L13: =MTS!G1 -> 0 | M13: =MTS!H1 -> 6 | N13: =MTS!I1 -> 3729
A14: 46035 | B14: =ACU!D15+AIB!D15+ARC!D15+AXS!D15+BOU!D15+BPO!D15+CSS!D15+MAM!D15+MED!D15+MEM!D15+MKT!D15+MTS!D15+NAV!D15+'NUM{THR}'!D15+PAR!D15+RAN!D15+RCO!D15+SA!D15+TFG!D15+TLD!D15 -> 0 | C14: =ACU!E15+AIB!E15+ARC!E15+AXS!E15+BOU!E15+BPO!E15+CSS!E15+MAM!E15+MED!E15+MEM!E15+MKT!E15+MTS!E15+NAV!E15+'NUM{THR}'!E15+PAR!E15+RAN!E15+RCO!E15+SA!E15+TFG!E15+TLD!E15 -> 0 | D14: =ACU!F15+AIB!F15+ARC!F15+AXS!F15+BOU!F15+BPO!F15+CSS!F15+MAM!F15+MED!F15+MEM!F15+MKT!F15+MTS!F15+NAV!F15+'NUM{THR}'!F15+PAR!F15+RAN!F15+RCO!F15+SA!F15+TFG!F15+TLD!F15 -> 0 | E14: =ACU!G15+AIB!G15+ARC!G15+AXS!G15+BOU!G15+BPO!G15+CSS!G15+MAM!G15+MED!G15+MEM!G15+MKT!G15+MTS!G15+NAV!G15+'NUM{THR}'!G15+PAR!G15+RAN!G15+RCO!G15+SA!G15+TFG!G15+TLD!G15 -> 0 | H14: NAV | I14: =NAV!D1 -> 36 | J14: =NAV!E1 -> 14944 | K14: =NAV!F1 -> 0 | L14: =NAV!G1 -> 0 | M14: =NAV!H1 -> 36 | N14: =NAV!I1 -> 14944
A15: 46036 | B15: =ACU!D16+AIB!D16+ARC!D16+AXS!D16+BOU!D16+BPO!D16+CSS!D16+MAM!D16+MED!D16+MEM!D16+MKT!D16+MTS!D16+NAV!D16+'NUM{THR}'!D16+PAR!D16+RAN!D16+RCO!D16+SA!D16+TFG!D16+TLD!D16 -> 39 | C15: =ACU!E16+AIB!E16+ARC!E16+AXS!E16+BOU!E16+BPO!E16+CSS!E16+MAM!E16+MED!E16+MEM!E16+MKT!E16+MTS!E16+NAV!E16+'NUM{THR}'!E16+PAR!E16+RAN!E16+RCO!E16+SA!E16+TFG!E16+TLD!E16 -> 39229 | D15: =ACU!F16+AIB!F16+ARC!F16+AXS!F16+BOU!F16+BPO!F16+CSS!F16+MAM!F16+MED!F16+MEM!F16+MKT!F16+MTS!F16+NAV!F16+'NUM{THR}'!F16+PAR!F16+RAN!F16+RCO!F16+SA!F16+TFG!F16+TLD!F16 -> 0 | E15: =ACU!G16+AIB!G16+ARC!G16+AXS!G16+BOU!G16+BPO!G16+CSS!G16+MAM!G16+MED!G16+MEM!G16+MKT!G16+MTS!G16+NAV!G16+'NUM{THR}'!G16+PAR!G16+RAN!G16+RCO!G16+SA!G16+TFG!G16+TLD!G16 -> 0 | H15: NUM {THR} | I15: ='NUM{THR}'!D1 -> 1 | J15: ='NUM{THR}'!E1 -> 665 | K15: ='NUM{THR}'!F1 -> 0 | L15: ='NUM{THR}'!G1 -> 0 | M15: ='NUM{THR}'!H1 -> 1 | N15: ='NUM{THR}'!I1 -> 665
A16: 46037 | B16: =ACU!D17+AIB!D17+ARC!D17+AXS!D17+BOU!D17+BPO!D17+CSS!D17+MAM!D17+MED!D17+MEM!D17+MKT!D17+MTS!D17+NAV!D17+'NUM{THR}'!D17+PAR!D17+RAN!D17+RCO!D17+SA!D17+TFG!D17+TLD!D17 -> 70 | C16: =ACU!E17+AIB!E17+ARC!E17+AXS!E17+BOU!E17+BPO!E17+CSS!E17+MAM!E17+MED!E17+MEM!E17+MKT!E17+MTS!E17+NAV!E17+'NUM{THR}'!E17+PAR!E17+RAN!E17+RCO!E17+SA!E17+TFG!E17+TLD!E17 -> 67666 | D16: =ACU!F17+AIB!F17+ARC!F17+AXS!F17+BOU!F17+BPO!F17+CSS!F17+MAM!F17+MED!F17+MEM!F17+MKT!F17+MTS!F17+NAV!F17+'NUM{THR}'!F17+PAR!F17+RAN!F17+RCO!F17+SA!F17+TFG!F17+TLD!F17 -> 0 | E16: =ACU!G17+AIB!G17+ARC!G17+AXS!G17+BOU!G17+BPO!G17+CSS!G17+MAM!G17+MED!G17+MEM!G17+MKT!G17+MTS!G17+NAV!G17+'NUM{THR}'!G17+PAR!G17+RAN!G17+RCO!G17+SA!G17+TFG!G17+TLD!G17 -> 0 | H16: PAR | I16: =PAR!D1 -> 716 | J16: =PAR!E1 -> 738011.5 | K16: =PAR!F1 -> 0 | L16: =PAR!G1 -> 0 | M16: =PAR!H1 -> 716 | N16: =PAR!I1 -> 738011.5
A17: 46038 | B17: =ACU!D18+AIB!D18+ARC!D18+AXS!D18+BOU!D18+BPO!D18+CSS!D18+MAM!D18+MED!D18+MEM!D18+MKT!D18+MTS!D18+NAV!D18+'NUM{THR}'!D18+PAR!D18+RAN!D18+RCO!D18+SA!D18+TFG!D18+TLD!D18 -> 8 | C17: =ACU!E18+AIB!E18+ARC!E18+AXS!E18+BOU!E18+BPO!E18+CSS!E18+MAM!E18+MED!E18+MEM!E18+MKT!E18+MTS!E18+NAV!E18+'NUM{THR}'!E18+PAR!E18+RAN!E18+RCO!E18+SA!E18+TFG!E18+TLD!E18 -> 9430 | D17: =ACU!F18+AIB!F18+ARC!F18+AXS!F18+BOU!F18+BPO!F18+CSS!F18+MAM!F18+MED!F18+MEM!F18+MKT!F18+MTS!F18+NAV!F18+'NUM{THR}'!F18+PAR!F18+RAN!F18+RCO!F18+SA!F18+TFG!F18+TLD!F18 -> 0 | E17: =ACU!G18+AIB!G18+ARC!G18+AXS!G18+BOU!G18+BPO!G18+CSS!G18+MAM!G18+MED!G18+MEM!G18+MKT!G18+MTS!G18+NAV!G18+'NUM{THR}'!G18+PAR!G18+RAN!G18+RCO!G18+SA!G18+TFG!G18+TLD!G18 -> 0 | H17: RAN | I17: =RAN!D1 -> 0 | J17: =RAN!E1 -> 0 | K17: =RAN!F1 -> 0 | L17: =RAN!G1 -> 0 | M17: =RAN!H1 -> 0 | N17: =RAN!I1 -> 0
A18: 46039 | B18: =ACU!D19+AIB!D19+ARC!D19+AXS!D19+BOU!D19+BPO!D19+CSS!D19+MAM!D19+MED!D19+MEM!D19+MKT!D19+MTS!D19+NAV!D19+'NUM{THR}'!D19+PAR!D19+RAN!D19+RCO!D19+SA!D19+TFG!D19+TLD!D19 -> 9 | C18: =ACU!E19+AIB!E19+ARC!E19+AXS!E19+BOU!E19+BPO!E19+CSS!E19+MAM!E19+MED!E19+MEM!E19+MKT!E19+MTS!E19+NAV!E19+'NUM{THR}'!E19+PAR!E19+RAN!E19+RCO!E19+SA!E19+TFG!E19+TLD!E19 -> 13435 | D18: =ACU!F19+AIB!F19+ARC!F19+AXS!F19+BOU!F19+BPO!F19+CSS!F19+MAM!F19+MED!F19+MEM!F19+MKT!F19+MTS!F19+NAV!F19+'NUM{THR}'!F19+PAR!F19+RAN!F19+RCO!F19+SA!F19+TFG!F19+TLD!F19 -> 0 | E18: =ACU!G19+AIB!G19+ARC!G19+AXS!G19+BOU!G19+BPO!G19+CSS!G19+MAM!G19+MED!G19+MEM!G19+MKT!G19+MTS!G19+NAV!G19+'NUM{THR}'!G19+PAR!G19+RAN!G19+RCO!G19+SA!G19+TFG!G19+TLD!G19 -> 0 | H18: RCO | I18: =RCO!D1 -> 1 | J18: =RCO!E1 -> 665 | K18: =RCO!F1 -> 0 | L18: =RCO!G1 -> 0 | M18: =RCO!H1 -> 1 | N18: =RCO!I1 -> 665
A19: 46040 | B19: =ACU!D20+AIB!D20+ARC!D20+AXS!D20+BOU!D20+BPO!D20+CSS!D20+MAM!D20+MED!D20+MEM!D20+MKT!D20+MTS!D20+NAV!D20+'NUM{THR}'!D20+PAR!D20+RAN!D20+RCO!D20+SA!D20+TFG!D20+TLD!D20 -> 0 | C19: =ACU!E20+AIB!E20+ARC!E20+AXS!E20+BOU!E20+BPO!E20+CSS!E20+MAM!E20+MED!E20+MEM!E20+MKT!E20+MTS!E20+NAV!E20+'NUM{THR}'!E20+PAR!E20+RAN!E20+RCO!E20+SA!E20+TFG!E20+TLD!E20 -> 0 | D19: =ACU!F20+AIB!F20+ARC!F20+AXS!F20+BOU!F20+BPO!F20+CSS!F20+MAM!F20+MED!F20+MEM!F20+MKT!F20+MTS!F20+NAV!F20+'NUM{THR}'!F20+PAR!F20+RAN!F20+RCO!F20+SA!F20+TFG!F20+TLD!F20 -> 0 | E19: =ACU!G20+AIB!G20+ARC!G20+AXS!G20+BOU!G20+BPO!G20+CSS!G20+MAM!G20+MED!G20+MEM!G20+MKT!G20+MTS!G20+NAV!G20+'NUM{THR}'!G20+PAR!G20+RAN!G20+RCO!G20+SA!G20+TFG!G20+TLD!G20 -> 0 | H19: SA | I19: =SA!D1 -> 892 | J19: =SA!E1 -> 959816.5 | K19: =SA!F1 -> 0 | L19: =SA!G1 -> 0 | M19: =SA!H1 -> 892 | N19: =SA!I1 -> 959816.5
A20: 46041 | B20: =ACU!D21+AIB!D21+ARC!D21+AXS!D21+BOU!D21+BPO!D21+CSS!D21+MAM!D21+MED!D21+MEM!D21+MKT!D21+MTS!D21+NAV!D21+'NUM{THR}'!D21+PAR!D21+RAN!D21+RCO!D21+SA!D21+TFG!D21+TLD!D21 -> 1 | C20: =ACU!E21+AIB!E21+ARC!E21+AXS!E21+BOU!E21+BPO!E21+CSS!E21+MAM!E21+MED!E21+MEM!E21+MKT!E21+MTS!E21+NAV!E21+'NUM{THR}'!E21+PAR!E21+RAN!E21+RCO!E21+SA!E21+TFG!E21+TLD!E21 -> 1131 | D20: =ACU!F21+AIB!F21+ARC!F21+AXS!F21+BOU!F21+BPO!F21+CSS!F21+MAM!F21+MED!F21+MEM!F21+MKT!F21+MTS!F21+NAV!F21+'NUM{THR}'!F21+PAR!F21+RAN!F21+RCO!F21+SA!F21+TFG!F21+TLD!F21 -> 0 | E20: =ACU!G21+AIB!G21+ARC!G21+AXS!G21+BOU!G21+BPO!G21+CSS!G21+MAM!G21+MED!G21+MEM!G21+MKT!G21+MTS!G21+NAV!G21+'NUM{THR}'!G21+PAR!G21+RAN!G21+RCO!G21+SA!G21+TFG!G21+TLD!G21 -> 0 | H20: TFG | I20: =TFG!D1 -> 2 | J20: =TFG!E1 -> 999 | K20: =TFG!F1 -> 0 | L20: =TFG!G1 -> 0 | M20: =TFG!H1 -> 2 | N20: =TFG!I1 -> 999
A21: 46042 | B21: =ACU!D22+AIB!D22+ARC!D22+AXS!D22+BOU!D22+BPO!D22+CSS!D22+MAM!D22+MED!D22+MEM!D22+MKT!D22+MTS!D22+NAV!D22+'NUM{THR}'!D22+PAR!D22+RAN!D22+RCO!D22+SA!D22+TFG!D22+TLD!D22 -> 25 | C21: =ACU!E22+AIB!E22+ARC!E22+AXS!E22+BOU!E22+BPO!E22+CSS!E22+MAM!E22+MED!E22+MEM!E22+MKT!E22+MTS!E22+NAV!E22+'NUM{THR}'!E22+PAR!E22+RAN!E22+RCO!E22+SA!E22+TFG!E22+TLD!E22 -> 25571 | D21: =ACU!F22+AIB!F22+ARC!F22+AXS!F22+BOU!F22+BPO!F22+CSS!F22+MAM!F22+MED!F22+MEM!F22+MKT!F22+MTS!F22+NAV!F22+'NUM{THR}'!F22+PAR!F22+RAN!F22+RCO!F22+SA!F22+TFG!F22+TLD!F22 -> 0 | E21: =ACU!G22+AIB!G22+ARC!G22+AXS!G22+BOU!G22+BPO!G22+CSS!G22+MAM!G22+MED!G22+MEM!G22+MKT!G22+MTS!G22+NAV!G22+'NUM{THR}'!G22+PAR!G22+RAN!G22+RCO!G22+SA!G22+TFG!G22+TLD!G22 -> 0 | H21: TLD | I21: =TLD!D1 -> 2 | J21: =TLD!E1 -> 1280 | K21: =TLD!F1 -> 0 | L21: =TLD!G1 -> 0 | M21: =TLD!H1 -> 2 | N21: =TLD!I1 -> 1280
A22: 46043 | B22: =ACU!D23+AIB!D23+ARC!D23+AXS!D23+BOU!D23+BPO!D23+CSS!D23+MAM!D23+MED!D23+MEM!D23+MKT!D23+MTS!D23+NAV!D23+'NUM{THR}'!D23+PAR!D23+RAN!D23+RCO!D23+SA!D23+TFG!D23+TLD!D23 -> 10 | C22: =ACU!E23+AIB!E23+ARC!E23+AXS!E23+BOU!E23+BPO!E23+CSS!E23+MAM!E23+MED!E23+MEM!E23+MKT!E23+MTS!E23+NAV!E23+'NUM{THR}'!E23+PAR!E23+RAN!E23+RCO!E23+SA!E23+TFG!E23+TLD!E23 -> 9586 | D22: =ACU!F23+AIB!F23+ARC!F23+AXS!F23+BOU!F23+BPO!F23+CSS!F23+MAM!F23+MED!F23+MEM!F23+MKT!F23+MTS!F23+NAV!F23+'NUM{THR}'!F23+PAR!F23+RAN!F23+RCO!F23+SA!F23+TFG!F23+TLD!F23 -> 0 | E22: =ACU!G23+AIB!G23+ARC!G23+AXS!G23+BOU!G23+BPO!G23+CSS!G23+MAM!G23+MED!G23+MEM!G23+MKT!G23+MTS!G23+NAV!G23+'NUM{THR}'!G23+PAR!G23+RAN!G23+RCO!G23+SA!G23+TFG!G23+TLD!G23 -> 0 | H22: TOTAL | I22: =SUBTOTAL(109,I2:I21) -> 2000 | J22: =SUBTOTAL(109,J2:J21) -> 2047657.8 | K22: =SUBTOTAL(109,K2:K21) -> 0 | L22: =SUBTOTAL(109,L2:L21) -> 0 | M22: =SUBTOTAL(109,M2:M21) -> 2000 | N22: =SUBTOTAL(109,N2:N21) -> 2047657.8
A23: 46044 | B23: =ACU!D24+AIB!D24+ARC!D24+AXS!D24+BOU!D24+BPO!D24+CSS!D24+MAM!D24+MED!D24+MEM!D24+MKT!D24+MTS!D24+NAV!D24+'NUM{THR}'!D24+PAR!D24+RAN!D24+RCO!D24+SA!D24+TFG!D24+TLD!D24 -> 3 | C23: =ACU!E24+AIB!E24+ARC!E24+AXS!E24+BOU!E24+BPO!E24+CSS!E24+MAM!E24+MED!E24+MEM!E24+MKT!E24+MTS!E24+NAV!E24+'NUM{THR}'!E24+PAR!E24+RAN!E24+RCO!E24+SA!E24+TFG!E24+TLD!E24 -> 2435 | D23: =ACU!F24+AIB!F24+ARC!F24+AXS!F24+BOU!F24+BPO!F24+CSS!F24+MAM!F24+MED!F24+MEM!F24+MKT!F24+MTS!F24+NAV!F24+'NUM{THR}'!F24+PAR!F24+RAN!F24+RCO!F24+SA!F24+TFG!F24+TLD!F24 -> 0 | E23: =ACU!G24+AIB!G24+ARC!G24+AXS!G24+BOU!G24+BPO!G24+CSS!G24+MAM!G24+MED!G24+MEM!G24+MKT!G24+MTS!G24+NAV!G24+'NUM{THR}'!G24+PAR!G24+RAN!G24+RCO!G24+SA!G24+TFG!G24+TLD!G24 -> 0
A24: 46045 | B24: =ACU!D25+AIB!D25+ARC!D25+AXS!D25+BOU!D25+BPO!D25+CSS!D25+MAM!D25+MED!D25+MEM!D25+MKT!D25+MTS!D25+NAV!D25+'NUM{THR}'!D25+PAR!D25+RAN!D25+RCO!D25+SA!D25+TFG!D25+TLD!D25 -> 0 | C24: =ACU!E25+AIB!E25+ARC!E25+AXS!E25+BOU!E25+BPO!E25+CSS!E25+MAM!E25+MED!E25+MEM!E25+MKT!E25+MTS!E25+NAV!E25+'NUM{THR}'!E25+PAR!E25+RAN!E25+RCO!E25+SA!E25+TFG!E25+TLD!E25 -> 0 | D24: =ACU!F25+AIB!F25+ARC!F25+AXS!F25+BOU!F25+BPO!F25+CSS!F25+MAM!F25+MED!F25+MEM!F25+MKT!F25+MTS!F25+NAV!F25+'NUM{THR}'!F25+PAR!F25+RAN!F25+RCO!F25+SA!F25+TFG!F25+TLD!F25 -> 0 | E24: =ACU!G25+AIB!G25+ARC!G25+AXS!G25+BOU!G25+BPO!G25+CSS!G25+MAM!G25+MED!G25+MEM!G25+MKT!G25+MTS!G25+NAV!G25+'NUM{THR}'!G25+PAR!G25+RAN!G25+RCO!G25+SA!G25+TFG!G25+TLD!G25 -> 0
A25: 46046 | B25: =ACU!D26+AIB!D26+ARC!D26+AXS!D26+BOU!D26+BPO!D26+CSS!D26+MAM!D26+MED!D26+MEM!D26+MKT!D26+MTS!D26+NAV!D26+'NUM{THR}'!D26+PAR!D26+RAN!D26+RCO!D26+SA!D26+TFG!D26+TLD!D26 -> 62 | C25: =ACU!E26+AIB!E26+ARC!E26+AXS!E26+BOU!E26+BPO!E26+CSS!E26+MAM!E26+MED!E26+MEM!E26+MKT!E26+MTS!E26+NAV!E26+'NUM{THR}'!E26+PAR!E26+RAN!E26+RCO!E26+SA!E26+TFG!E26+TLD!E26 -> 68796 | D25: =ACU!F26+AIB!F26+ARC!F26+AXS!F26+BOU!F26+BPO!F26+CSS!F26+MAM!F26+MED!F26+MEM!F26+MKT!F26+MTS!F26+NAV!F26+'NUM{THR}'!F26+PAR!F26+RAN!F26+RCO!F26+SA!F26+TFG!F26+TLD!F26 -> 0 | E25: =ACU!G26+AIB!G26+ARC!G26+AXS!G26+BOU!G26+BPO!G26+CSS!G26+MAM!G26+MED!G26+MEM!G26+MKT!G26+MTS!G26+NAV!G26+'NUM{THR}'!G26+PAR!G26+RAN!G26+RCO!G26+SA!G26+TFG!G26+TLD!G26 -> 0
A26: 46047 | B26: =ACU!D27+AIB!D27+ARC!D27+AXS!D27+BOU!D27+BPO!D27+CSS!D27+MAM!D27+MED!D27+MEM!D27+MKT!D27+MTS!D27+NAV!D27+'NUM{THR}'!D27+PAR!D27+RAN!D27+RCO!D27+SA!D28+TFG!D27+TLD!D27 -> 143 | C26: =ACU!E27+AIB!E27+ARC!E27+AXS!E27+BOU!E27+BPO!E27+CSS!E27+MAM!E27+MED!E27+MEM!E27+MKT!E27+MTS!E27+NAV!E27+'NUM{THR}'!E27+PAR!E27+RAN!E27+RCO!E27+SA!E28+TFG!E27+TLD!E27 -> 159576 | D26: =ACU!F27+AIB!F27+ARC!F27+AXS!F27+BOU!F27+BPO!F27+CSS!F27+MAM!F27+MED!F27+MEM!F27+MKT!F27+MTS!F27+NAV!F27+'NUM{THR}'!F27+PAR!F27+RAN!F27+RCO!F27+SA!F28+TFG!F27+TLD!F27 -> 0 | E26: =ACU!G27+AIB!G27+ARC!G27+AXS!G27+BOU!G27+BPO!G27+CSS!G27+MAM!G27+MED!G27+MEM!G27+MKT!G27+MTS!G27+NAV!G27+'NUM{THR}'!G27+PAR!G27+RAN!G27+RCO!G27+SA!G28+TFG!G27+TLD!G27 -> 0
A27: 46048 | B27: =ACU!D28+AIB!D28+ARC!D28+AXS!D28+BOU!D28+BPO!D28+CSS!D28+MAM!D28+MED!D28+MEM!D28+MKT!D28+MTS!D28+NAV!D28+'NUM{THR}'!D28+PAR!D28+RAN!D28+RCO!D28+SA!D29+TFG!D28+TLD!D28 -> 180 | C27: =ACU!E28+AIB!E28+ARC!E28+AXS!E28+BOU!E28+BPO!E28+CSS!E28+MAM!E28+MED!E28+MEM!E28+MKT!E28+MTS!E28+NAV!E28+'NUM{THR}'!E28+PAR!E28+RAN!E28+RCO!E28+SA!E29+TFG!E28+TLD!E28 -> 175030 | D27: =ACU!F28+AIB!F28+ARC!F28+AXS!F28+BOU!F28+BPO!F28+CSS!F28+MAM!F28+MED!F28+MEM!F28+MKT!F28+MTS!F28+NAV!F28+'NUM{THR}'!F28+PAR!F28+RAN!F28+RCO!F28+SA!F29+TFG!F28+TLD!F28 -> 0 | E27: =ACU!G28+AIB!G28+ARC!G28+AXS!G28+BOU!G28+BPO!G28+CSS!G28+MAM!G28+MED!G28+MEM!G28+MKT!G28+MTS!G28+NAV!G28+'NUM{THR}'!G28+PAR!G28+RAN!G28+RCO!G28+SA!G29+TFG!G28+TLD!G28 -> 0
A28: 46049 | B28: =ACU!D29+AIB!D29+ARC!D29+AXS!D29+BOU!D29+BPO!D29+CSS!D29+MAM!D29+MED!D29+MEM!D29+MKT!D29+MTS!D29+NAV!D29+'NUM{THR}'!D29+PAR!D29+RAN!D29+RCO!D29+SA!D30+TFG!D29+TLD!D29 -> 105 | C28: =ACU!E29+AIB!E29+ARC!E29+AXS!E29+BOU!E29+BPO!E29+CSS!E29+MAM!E29+MED!E29+MEM!E29+MKT!E29+MTS!E29+NAV!E29+'NUM{THR}'!E29+PAR!E29+RAN!E29+RCO!E29+SA!E30+TFG!E29+TLD!E29 -> 95693 | D28: =ACU!F29+AIB!F29+ARC!F29+AXS!F29+BOU!F29+BPO!F29+CSS!F29+MAM!F29+MED!F29+MEM!F29+MKT!F29+MTS!F29+NAV!F29+'NUM{THR}'!F29+PAR!F29+RAN!F29+RCO!F29+SA!F30+TFG!F29+TLD!F29 -> 0 | E28: =ACU!G29+AIB!G29+ARC!G29+AXS!G29+BOU!G29+BPO!G29+CSS!G29+MAM!G29+MED!G29+MEM!G29+MKT!G29+MTS!G29+NAV!G29+'NUM{THR}'!G29+PAR!G29+RAN!G29+RCO!G29+SA!G30+TFG!G29+TLD!G29 -> 0
A29: 46050 | B29: =ACU!D30+AIB!D30+ARC!D30+AXS!D30+BOU!D30+BPO!D30+CSS!D30+MAM!D30+MED!D30+MEM!D30+MKT!D30+MTS!D30+NAV!D30+'NUM{THR}'!D30+PAR!D30+RAN!D30+RCO!D30+SA!D31+TFG!D30+TLD!D30 -> 52 | C29: =ACU!E30+AIB!E30+ARC!E30+AXS!E30+BOU!E30+BPO!E30+CSS!E30+MAM!E30+MED!E30+MEM!E30+MKT!E30+MTS!E30+NAV!E30+'NUM{THR}'!E30+PAR!E30+RAN!E30+RCO!E30+SA!E31+TFG!E30+TLD!E30 -> 44352.75 | D29: =ACU!F30+AIB!F30+ARC!F30+AXS!F30+BOU!F30+BPO!F30+CSS!F30+MAM!F30+MED!F30+MEM!F30+MKT!F30+MTS!F30+NAV!F30+'NUM{THR}'!F30+PAR!F30+RAN!F30+RCO!F30+SA!F31+TFG!F30+TLD!F30 -> 0 | E29: =ACU!G30+AIB!G30+ARC!G30+AXS!G30+BOU!G30+BPO!G30+CSS!G30+MAM!G30+MED!G30+MEM!G30+MKT!G30+MTS!G30+NAV!G30+'NUM{THR}'!G30+PAR!G30+RAN!G30+RCO!G30+SA!G31+TFG!G30+TLD!G30 -> 0
A30: 46051 | B30: =ACU!D31+AIB!D31+ARC!D31+AXS!D31+BOU!D31+BPO!D31+CSS!D31+MAM!D31+MED!D31+MEM!D31+MKT!D31+MTS!D31+NAV!D31+'NUM{THR}'!D31+PAR!D31+RAN!D31+RCO!D31+SA!D32+TFG!D31+TLD!D31 -> 66 | C30: =ACU!E31+AIB!E31+ARC!E31+AXS!E31+BOU!E31+BPO!E31+CSS!E31+MAM!E31+MED!E31+MEM!E31+MKT!E31+MTS!E31+NAV!E31+'NUM{THR}'!E31+PAR!E31+RAN!E31+RCO!E31+SA!E32+TFG!E31+TLD!E31 -> 64992.75 | D30: =ACU!F31+AIB!F31+ARC!F31+AXS!F31+BOU!F31+BPO!F31+CSS!F31+MAM!F31+MED!F31+MEM!F31+MKT!F31+MTS!F31+NAV!F31+'NUM{THR}'!F31+PAR!F31+RAN!F31+RCO!F31+SA!F32+TFG!F31+TLD!F31 -> 0 | E30: =ACU!G31+AIB!G31+ARC!G31+AXS!G31+BOU!G31+BPO!G31+CSS!G31+MAM!G31+MED!G31+MEM!G31+MKT!G31+MTS!G31+NAV!G31+'NUM{THR}'!G31+PAR!G31+RAN!G31+RCO!G31+SA!G32+TFG!G31+TLD!G31 -> 0
A31: 46052 | B31: =ACU!D32+AIB!D32+ARC!D32+AXS!D32+BOU!D32+BPO!D32+CSS!D32+MAM!D32+MED!D32+MEM!D32+MKT!D32+MTS!D32+NAV!D32+'NUM{THR}'!D32+PAR!D32+RAN!D32+RCO!D32+SA!D33+TFG!D32+TLD!D32 -> 148 | C31: =ACU!E32+AIB!E32+ARC!E32+AXS!E32+BOU!E32+BPO!E32+CSS!E32+MAM!E32+MED!E32+MEM!E32+MKT!E32+MTS!E32+NAV!E32+'NUM{THR}'!E32+PAR!E32+RAN!E32+RCO!E32+SA!E33+TFG!E32+TLD!E32 -> 151943.75 | D31: =ACU!F32+AIB!F32+ARC!F32+AXS!F32+BOU!F32+BPO!F32+CSS!F32+MAM!F32+MED!F32+MEM!F32+MKT!F32+MTS!F32+NAV!F32+'NUM{THR}'!F32+PAR!F32+RAN!F32+RCO!F32+SA!F33+TFG!F32+TLD!F32 -> 0 | E31: =ACU!G32+AIB!G32+ARC!G32+AXS!G32+BOU!G32+BPO!G32+CSS!G32+MAM!G32+MED!G32+MEM!G32+MKT!G32+MTS!G32+NAV!G32+'NUM{THR}'!G32+PAR!G32+RAN!G32+RCO!G32+SA!G33+TFG!G32+TLD!G32 -> 0
A32: 46053 | B32: =ACU!D33+AIB!D33+ARC!D33+AXS!D33+BOU!D33+BPO!D33+CSS!D33+MAM!D33+MED!D33+MEM!D33+MKT!D33+MTS!D33+NAV!D33+'NUM{THR}'!D33+PAR!D33+RAN!D33+RCO!D33+SA!D34+TFG!D33+TLD!D33 -> 112 | C32: =ACU!E33+AIB!E33+ARC!E33+AXS!E33+BOU!E33+BPO!E33+CSS!E33+MAM!E33+MED!E33+MEM!E33+MKT!E33+MTS!E33+NAV!E33+'NUM{THR}'!E33+PAR!E33+RAN!E33+RCO!E33+SA!E34+TFG!E33+TLD!E33 -> 114899 | D32: =ACU!F33+AIB!F33+ARC!F33+AXS!F33+BOU!F33+BPO!F33+CSS!F33+MAM!F33+MED!F33+MEM!F33+MKT!F33+MTS!F33+NAV!F33+'NUM{THR}'!F33+PAR!F33+RAN!F33+RCO!F33+SA!F34+TFG!F33+TLD!F33 -> 0 | E32: =ACU!G33+AIB!G33+ARC!G33+AXS!G33+BOU!G33+BPO!G33+CSS!G33+MAM!G33+MED!G33+MEM!G33+MKT!G33+MTS!G33+NAV!G33+'NUM{THR}'!G33+PAR!G33+RAN!G33+RCO!G33+SA!G34+TFG!G33+TLD!G33 -> 0
B33: =SUBTOTAL(109,B2:B32) -> 1999 | C33: =SUBTOTAL(109,C2:C32) -> 2047332.8 | D33: =SUBTOTAL(109,D2:D32) -> 0 | E33: =SUBTOTAL(109,E2:E32) -> 0

Sheet ACU
D1: =D3+D4+D5+D6+D7+D8+D9+D10+D11+D12+D13+D14+D15+D16+D17+D18+D19+D20+D21+D22+D23+D24+D25+D26+D27+D28+D29+D30+D31+D32+D33 -> 1 | E1: =E3+E4+E5+E6+E7+E8+E9+E10+E11+E12+E13+E14+E15+E16+E17+E18+E19+E20+E21+E22+E23+E24+E25+E26+E27+E28+E29+E30+E31+E32+E33 -> 578 | F1: =F3+F4+F5+F6+F7+F8+F9+F10+F11+F12+F13+F14+F15+F16+F17+F18+F19+F20+F21+F22+F23+F24+F25+F26+F27+F28+F29+F30+F31+F32+F33 -> 0 | G1: =G3+G4+G5+G6+G7+G8+G9+G10+G11+G12+G13+G14+G15+G16+G17+G18+G19+G20+G21+G22+G23+G24+G25+G26+G27+G28+G29+G30+G31+G32+G33 -> 0 | H1: =H3+H4+H5+H6+H7+H8+H9+H10+H11+H12+H13+H14+H15+H16+H17+H18+H19+H20+H21+H22+H23+H24+H25+H26+H27+H28+H29+H30+H31+H32+H33 -> 1 | I1: =I3+I4+I5+I6+I7+I8+I9+I10+I11+I12+I13+I14+I15+I16+I17+I18+I19+I20+I21+I22+I23+I24+I25+I26+I27+I28+I29+I30+I31+I32+I33 -> 578
A2: Import Date | B2: Batch Number | C2: Strike Date | D2: Received Volume | E2: Received Value | F2: Rejected Volume | G2: Rejected Value | H2: Accepted Volume | I2: Accepted Value
C3: 46023
C4: 46024
C5: 46025
C6: 46026
C7: 46027
C8: 46028
C9: 46029
C10: 46030
C11: 46031
C12: 46032
C13: 46033
C14: 46034
... C30: 46050
A31: 46045 | B31: 65 | C31: 46051 | D31: 1 | E31: 578 | F31: 0 | G31: 0 | H31: 1 | I31: 578
C32: 46052
C33: 46053

Sheet AIB
D1: =D3+D4+D5+D6+D7+D8+D9+D10+D11+D12+D13+D14+D15+D16+D17+D18+D19+D20+D21+D22+D23+D24+D25+D26+D27+D28+D29+D30+D31+D32+D33 -> 12 | E1: =E3+E4+E5+E6+E7+E8+E9+E10+E11+E12+E13+E14+E15+E16+E17+E18+E19+E20+E21+E22+E23+E24+E25+E26+E27+E28+E29+E30+E31+E32+E33 -> 9589 | F1: =F3+F4+F5+F6+F7+F8+F9+F10+F11+F12+F13+F14+F15+F16+F17+F18+F19+F20+F21+F22+F23+F24+F25+F26+F27+F28+F29+F30+F31+F32+F33 -> 0 | G1: =G3+G4+G5+G6+G7+G8+G9+G10+G11+G12+G13+G14+G15+G16+G17+G18+G19+G20+G21+G22+G23+G24+G25+G26+G27+G28+G29+G30+G31+G32+G33 -> 0 | H1: =H3+H4+H5+H6+H7+H8+H9+H10+H11+H12+H13+H14+H15+H16+H17+H18+H19+H20+H21+H22+H23+H24+H25+H26+H27+H28+H29+H30+H31+H32+H33 -> 12 | I1: =I3+I4+I5+I6+I7+I8+I9+I10+I11+I12+I13+I14+I15+I16+I17+I18+I19+I20+I21+I22+I23+I24+I25+I26+I27+I28+I29+I30+I31+I32+I33 -> 9589
A2: Import Date | B2: Batch Number | C2: Strike Date | D2: Received Volume | E2: Received Value | F2: Rejected Volume | G2: Rejected Value | H2: Accepted Volume | I2: Accepted Value
C3: 46023
A4: 46018 | B4: 322 | C4: 46024 | D4: 4 | E4: 3911 | F4: 0 | G4: 0 | H4: 4 | I4: 3911
C5: 46025
C6: 46026
C7: 46027
C8: 46028
A9: 46024 | B9: 323 | C9: 46029 | D9: 2 | E9: 1316 | F9: 0 | G9: 0 | H9: 2 | I9: 1316
C10: 46030
C11: 46031
C12: 46032
C13: 46033
C14: 46034
C15: 46035
C16: 46036
C17: 46037
C18: 46038
C19: 46039
C20: 46040
C21: 46041
... C27: 46047
A28: 46045 | B28: 324 | C28: 46048 | D28: 2 | E28: 1782 | F28: 0 | G28: 0 | H28: 2 | I28: 1782
A29: 46045 | B29: 324 | C29: 46049 | D29: 2 | E29: 1320 | F29: 0 | G29: 0 | H29: 2 | I29: 1320
C30: 46050
A31: 46045 | B31: 324 | C31: 46051 | D31: 1 | E31: 325 | F31: 0 | G31: 0 | H31: 1 | I31: 325
C32: 46052
A33: 46050 | B33: 326 | C33: 46053 | D33: 1 | E33: 935 | F33: 0 | G33: 0 | H33: 1 | I33: 935

Sheet ARC
D1: =D3+D4+D5+D6+D7+D8+D9+D10+D11+D12+D13+D14+D15+D16+D17+D18+D19+D20+D21+D22+D23+D24+D25+D26+D27+D28+D29+D30+D31+D32+D33 -> 16 | E1: =E3+E4+E5+E6+E7+E8+E9+E10+E11+E12+E13+E14+E15+E16+E17+E18+E19+E20+E21+E22+E23+E24+E25+E26+E27+E28+E29+E30+E31+E32+E33 -> 18078 | F1: =F3+F4+F5+F6+F7+F8+F9+F10+F11+F12+F13+F14+F15+F16+F17+F18+F19+F20+F21+F22+F23+F24+F25+F26+F27+F28+F29+F30+F31+F32+F33 -> 0 | G1: =G3+G4+G5+G6+G7+G8+G9+G10+G11+G12+G13+G14+G15+G16+G17+G18+G19+G20+G21+G22+G23+G24+G25+G26+G27+G28+G29+G30+G31+G32+G33 -> 0 | H1: =H3+H4+H5+H6+H7+H8+H9+H10+H11+H12+H13+H14+H15+H16+H17+H18+H19+H20+H21+H22+H23+H24+H25+H26+H27+H28+H29+H30+H31+H32+H33 -> 16 | I1: =I3+I4+I5+I6+I7+I8+I9+I10+I11+I12+I13+I14+I15+I16+I17+I18+I19+I20+I21+I22+I23+I24+I25+I26+I27+I28+I29+I30+I31+I32+I33 -> 18078
A2: Import Date | B2: Batch Number | C2: Strike Date | D2: Received Volume | E2: Received Value | F2: Rejected Volume | G2: Rejected Value | H2: Accepted Volume | I2: Accepted Value
C3: 46023
A4: 46018 | B4: 261 | C4: 46024 | D4: 7 | E4: 10011 | F4: 0 | G4: 0 | H4: 7 | I4: 10011
C5: 46025
C6: 46026
C7: 46027
A8: 46024 | B8: 262 | C8: 46028 | D8: 1 | E8: 385 | F8: 0 | G8: 0 | H8: 1 | I8: 385
C9: 46029
C10: 46030
C11: 46031
C12: 46032
C13: 46033
C14: 46034
C15: 46035
C16: 46036
C17: 46037
C18: 46038
C19: 46039
C20: 46040
... C25: 46045
A26: 46045 | B26: 264 | C26: 46046 | D26: 1 | E26: 665 | F26: 0 | G26: 0 | H26: 1 | I26: 665
C27: 46047
A28: 46045 | B28: 264 | C28: 46048 | D28: 1 | E28: 665 | F28: 0 | G28: 0 | H28: 1 | I28: 665
A29: 46045 | B29: 264 | C29: 46049 | D29: 3 | E29: 3190 | F29: 0 | G29: 0 | H29: 3 | I29: 3190
C30: 46050
C31: 46051
A32: 46050 | B32: 267 | C32: 46052 | D32: 1 | E32: 947 | F32: 0 | G32: 0 | H32: 1 | I32: 947
A33: 46050 | B33: 267 | C33: 46053 | D33: 2 | E33: 2215 | F33: 0 | G33: 0 | H33: 2 | I33: 2215

Sheet AXS
D1: =D3+D4+D5+D6+D7+D8+D9+D10+D11+D12+D13+D14+D15+D16+D17+D18+D19+D20+D21+D22+D23+D24+D25+D26+D27+D28+D29+D30+D31+D32+D33 -> 15 | E1: =E3+E4+E5+E6+E7+E8+E9+E10+E11+E12+E13+E14+E15+E16+E17+E18+E19+E20+E21+E22+E23+E24+E25+E26+E27+E28+E29+E30+E31+E32+E33 -> 11591 | F1: =F3+F4+F5+F6+F7+F8+F9+F10+F11+F12+F13+F14+F15+F16+F17+F18+F19+F20+F21+F22+F23+F24+F25+F26+F27+F28+F29+F30+F31+F32+F33 -> 0 | G1: =G3+G4+G5+G6+G7+G8+G9+G10+G11+G12+G13+G14+G15+G16+G17+G18+G19+G20+G21+G22+G23+G24+G25+G26+G27+G28+G29+G30+G31+G32+G33 -> 0 | H1: =H3+H4+H5+H6+H7+H8+H9+H10+H11+H12+H13+H14+H15+H16+H17+H18+H19+H20+H21+H22+H23+H24+H25+H26+H27+H28+H29+H30+H31+H32+H33 -> 15 | I1: =I3+I4+I5+I6+I7+I8+I9+I10+I11+I12+I13+I14+I15+I16+I17+I18+I19+I20+I21+I22+I23+I24+I25+I26+I27+I28+I29+I30+I31+I32+I33 -> 11591
A2: Import Date | B2: Batch Number | C2: Strike Date | D2: Received Volume | E2: Received Value | F2: Rejected Volume | G2: Rejected Value | H2: Accepted Volume | I2: Accepted Value
C3: 46023
A4: 46018 | B4: 405 | C4: 46024 | D4: 4 | E4: 2889 | F4: 0 | G4: 0 | H4: 4 | I4: 2889
C5: 46025
C6: 46026
C7: 46027
C8: 46028
A9: 46024 | B9: 406 | C9: 46029 | D9: 1 | E9: 947 | F9: 0 | G9: 0 | H9: 1 | I9: 947
C10: 46030
C11: 46031
C12: 46032
C13: 46033
C14: 46034
C15: 46035
A16: 46031 | B16: 407 | C16: 46036 | D16: 1 | E16: 947 | F16: 0 | G16: 0 | H16: 1 | I16: 947
A17: 46031 | B17: 407 | C17: 46037 | D17: 2 | E17: 2078 | F17: 0 | G17: 0 | H17: 2 | I17: 2078
A18: 46035 | B18: 408 | C18: 46038 | D18: 1 | E18: 565 | F18: 0 | G18: 0 | H18: 1 | I18: 565
C19: 46039
C20: 46040
C21: 46041
C22: 46042
C23: 46043
C24: 46044
C25: 46045
C26: 46046
C27: 46047
A28: 46045 | B28: 409 | C28: 46048 | D28: 1 | E28: 565 | F28: 0 | G28: 0 | H28: 1 | I28: 565
A29: 46045 | B29: 409 | C29: 46049 | D29: 1 | E29: 565 | F29: 0 | G29: 0 | H29: 1 | I29: 565
A30: 46045 | B30: 409 | C30: 46050 | D30: 1 | E30: 425 | F30: 0 | G30: 0 | H30: 1 | I30: 425
C31: 46051
C32: 46052
A33: 46050 | B33: 411 | C33: 46053 | D33: 3 | E33: 2610 | F33: 0 | G33: 0 | H33: 3 | I33: 2610

Sheet BOU
D1: =D3+D4+D5+D6+D7+D8+D9+D10+D11+D12+D13+D14+D15+D16+D17+D18+D19+D20+D21+D22+D23+D24+D25+D26+D27+D28+D29+D30+D31+D32+D33 -> 2 | E1: =E3+E4+E5+E6+E7+E8+E9+E10+E11+E12+E13+E14+E15+E16+E17+E18+E19+E20+E21+E22+E23+E24+E25+E26+E27+E28+E29+E30+E31+E32+E33 -> 1560 | F1: =F3+F4+F5+F6+F7+F8+F9+F10+F11+F12+F13+F14+F15+F16+F17+F18+F19+F20+F21+F22+F23+F24+F25+F26+F27+F28+F29+F30+F31+F32+F33 -> 0 | G1: =G3+G4+G5+G6+G7+G8+G9+G10+G11+G12+G13+G14+G15+G16+G17+G18+G19+G20+G21+G22+G23+G24+G25+G26+G27+G28+G29+G30+G31+G32+G33 -> 0 | H1: =H3+H4+H5+H6+H7+H8+H9+H10+H11+H12+H13+H14+H15+H16+H17+H18+H19+H20+H21+H22+H23+H24+H25+H26+H27+H28+H29+H30+H31+H32+H33 -> 2 | I1: =I3+I4+I5+I6+I7+I8+I9+I10+I11+I12+I13+I14+I15+I16+I17+I18+I19+I20+I21+I22+I23+I24+I25+I26+I27+I28+I29+I30+I31+I32+I33 -> 1560
A2: Import Date | B2: Batch Number | C2: Strike Date | D2: Received Volume | E2: Received Value | F2: Rejected Volume | G2: Rejected Value | H2: Accepted Volume | I2: Accepted Value
C3: 46023
C4: 46024
C5: 46025
C6: 46026
C7: 46027
C8: 46028
C9: 46029
C10: 46030
C11: 46031
C12: 46032
C13: 46033
C14: 46034
... C23: 46043
A24: 46041 | B24: 387 | C24: 46044 | D24: 1 | E24: 895 | F24: 0 | G24: 0 | H24: 1 | I24: 895
C25: 46045
C26: 46046
C27: 46047
A28: 46045 | B28: 388 | C28: 46048 | D28: 1 | E28: 665 | F28: 0 | G28: 0 | H28: 1 | I28: 665
C29: 46049
C30: 46050
C31: 46051
C32: 46052
C33: 46053

Sheet BPO
D1: =D3+D4+D5+D6+D7+D8+D9+D10+D11+D12+D13+D14+D15+D16+D17+D18+D19+D20+D21+D22+D23+D24+D25+D26+D27+D28+D29+D30+D31+D32+D33 -> 6 | E1: =E3+E4+E5+E6+E7+E8+E9+E10+E11+E12+E13+E14+E15+E16+E17+E18+E19+E20+E21+E22+E23+E24+E25+E26+E27+E28+E29+E30+E31+E32+E33 -> 6302 | F1: =F3+F4+F5+F6+F7+F8+F9+F10+F11+F12+F13+F14+F15+F16+F17+F18+F19+F20+F21+F22+F23+F24+F25+F26+F27+F28+F29+F30+F31+F32+F33 -> 0 | G1: =G3+G4+G5+G6+G7+G8+G9+G10+G11+G12+G13+G14+G15+G16+G17+G18+G19+G20+G21+G22+G23+G24+G25+G26+G27+G28+G29+G30+G31+G32+G33 -> 0 | H1: =H3+H4+H5+H6+H7+H8+H9+H10+H11+H12+H13+H14+H15+H16+H17+H18+H19+H20+H21+H22+H23+H24+H25+H26+H27+H28+H29+H30+H31+H32+H33 -> 6 | I1: =I3+I4+I5+I6+I7+I8+I9+I10+I11+I12+I13+I14+I15+I16+I17+I18+I19+I20+I21+I22+I23+I24+I25+I26+I27+I28+I29+I30+I31+I32+I33 -> 6302
A2: Import Date | B2: Batch Number | C2: Strike Date | D2: Received Volume | E2: Received Value | F2: Rejected Volume | G2: Rejected Value | H2: Accepted Volume | I2: Accepted Value
C3: 46023
C4: 46024
A5: 46021 | B5: 198 | C5: 46025 | D5: 1 | E5: 935 | F5: 0 | G5: 0 | H5: 1 | I5: 935
C6: 46026
C7: 46027
C8: 46028
C9: 46029
C10: 46030
C11: 46031
C12: 46032
C13: 46033
C14: 46034
C15: 46035
C16: 46036
C17: 46037
... C20: 46040
A21: 46035 | B21: 199 | C21: 46041 | D21: 1 | E21: 1131 | F21: 0 | G21: 0 | H21: 1 | I21: 1131
C22: 46042
C23: 46043
C24: 46044
C25: 46045
A26: 46045 | B26: 200 | C26: 46046 | D26: 1 | E26: 875 | F26: 0 | G26: 0 | H26: 1 | I26: 875
C27: 46047
C28: 46048
C29: 46049
C30: 46050
C31: 46051
A32: 46050 | B32: 202 | C32: 46052 | D32: 2 | E32: 2486 | F32: 0 | G32: 0 | H32: 2 | I32: 2486
A33: 46050 | B33: 202 | C33: 46053 | D33: 1 | E33: 875 | F33: 0 | G33: 0 | H33: 1 | I33: 875

Sheet CSS
D1: =D3+D4+D5+D6+D7+D8+D9+D10+D11+D12+D13+D14+D15+D16+D17+D18+D19+D20+D21+D22+D23+D24+D25+D26+D27+D28+D29+D30+D31+D32+D33 -> 2 | E1: =E3+E4+E5+E6+E7+E8+E9+E10+E11+E12+E13+E14+E15+E16+E17+E18+E19+E20+E21+E22+E23+E24+E25+E26+E27+E28+E29+E30+E31+E32+E33 -> 1055 | F1: =F3+F4+F5+F6+F7+F8+F9+F10+F11+F12+F13+F14+F15+F16+F17+F18+F19+F20+F21+F22+F23+F24+F25+F26+F27+F28+F29+F30+F31+F32+F33 -> 0 | G1: =G3+G4+G5+G6+G7+G8+G9+G10+G11+G12+G13+G14+G15+G16+G17+G18+G19+G20+G21+G22+G23+G24+G25+G26+G27+G28+G29+G30+G31+G32+G33 -> 0 | H1: =H3+H4+H5+H6+H7+H8+H9+H10+H11+H12+H13+H14+H15+H16+H17+H18+H19+H20+H21+H22+H23+H24+H25+H26+H27+H28+H29+H30+H31+H32+H33 -> 2 | I1: =I3+I4+I5+I6+I7+I8+I9+I10+I11+I12+I13+I14+I15+I16+I17+I18+I19+I20+I21+I22+I23+I24+I25+I26+I27+I28+I29+I30+I31+I32+I33 -> 1055
A2: Import Date | B2: Batch Number | C2: Strike Date | D2: Received Volume | E2: Received Value | F2: Rejected Volume | G2: Rejected Value | H2: Accepted Volume | I2: Accepted Value
C3: 46023
C4: 46024
C5: 46025
C6: 46026
C7: 46027
C8: 46028
C9: 46029
C10: 46030
C11: 46031
C12: 46032
C13: 46033
C14: 46034
... C16: 46036
A17: 46031 | B17: 272 | C17: 46037 | D17: 1 | E17: 665 | F17: 0 | G17: 0 | H17: 1 | I17: 665
C18: 46038
C19: 46039
C20: 46040
C21: 46041
C22: 46042
C23: 46043
C24: 46044
C25: 46045
C26: 46046
C27: 46047
C28: 46048
C29: 46049
... C32: 46052
A33: 46050 | B33: 273 | C33: 46053 | D33: 1 | E33: 390 | F33: 0 | G33: 0 | H33: 1 | I33: 390

Sheet MAM
D1: =D3+D4+D5+D6+D7+D8+D9+D10+D11+D12+D13+D14+D15+D16+D17+D18+D19+D20+D21+D22+D23+D24+D25+D26+D27+D28+D29+D30+D31+D32+D33 -> 163 | E1: =E3+E4+E5+E6+E7+E8+E9+E10+E11+E12+E13+E14+E15+E16+E17+E18+E19+E20+E21+E22+E23+E24+E25+E26+E27+E28+E29+E30+E31+E32+E33 -> 161530.25 | F1: =F3+F4+F5+F6+F7+F8+F9+F10+F11+F12+F13+F14+F15+F16+F17+F18+F19+F20+F21+F22+F23+F24+F25+F26+F27+F28+F29+F30+F31+F32+F33 -> 0 | G1: =G3+G4+G5+G6+G7+G8+G9+G10+G11+G12+G13+G14+G15+G16+G17+G18+G19+G20+G21+G22+G23+G24+G25+G26+G27+G28+G29+G30+G31+G32+G33 -> 0 | H1: =H3+H4+H5+H6+H7+H8+H9+H10+H11+H12+H13+H14+H15+H16+H17+H18+H19+H20+H21+H22+H23+H24+H25+H26+H27+H28+H29+H30+H31+H32+H33 -> 163 | I1: =I3+I4+I5+I6+I7+I8+I9+I10+I11+I12+I13+I14+I15+I16+I17+I18+I19+I20+I21+I22+I23+I24+I25+I26+I27+I28+I29+I30+I31+I32+I33 -> 161530.25
A2: Import Date | B2: Batch Number | C2: Strike Date | D2: Received Volume | E2: Received Value | F2: Rejected Volume | G2: Rejected Value | H2: Accepted Volume | I2: Accepted Value
C3: 46023
A4: 46018 | B4: 582&583 | C4: 46024 | D4: 56 | E4: 54790.75 | F4: 0 | G4: 0 | H4: 56 | I4: 54790.75
A5: 46021 | B5: 583 | C5: 46025 | D5: 2 | E5: 2655 | F5: 0 | G5: 0 | H5: 2 | I5: 2655
C6: 46026
A7: 46021 | B7: 583 | C7: 46027 | D7: 7 | E7: 6191 | F7: 0 | G7: 0 | H7: 7 | I7: 6191
A8: 46024 | B8: 584 | C8: 46028 | D8: 3 | E8: 2498 | F8: 0 | G8: 0 | H8: 3 | I8: 2498
A9: 46024 | B9: 584 | C9: 46029 | D9: 3 | E9: 3901 | F9: 0 | G9: 0 | H9: 3 | I9: 3901
C10: 46030
C11: 46031
A12: 46028 | B12: 585 | C12: 46032 | D12: 3 | E12: 5465.5 | F12: 0 | G12: 0 | H12: 3 | I12: 5465.5
C13: 46033
A14: 46028 | B14: 585 | C14: 46034 | D14: 1 | E14: 1591 | F14: 0 | G14: 0 | H14: 1 | I14: 1591
C15: 46035
A16: 46031 | B16: 586 | C16: 46036 | D16: 1 | E16: 931 | F16: 0 | G16: 0 | H16: 1 | I16: 931
A17: 46031 | B17: 586 | C17: 46037 | D17: 7 | E17: 6253 | F17: 0 | G17: 0 | H17: 7 | I17: 6253
C18: 46038
C19: 46039
C20: 46040
C21: 46041
A22: 46041 | B22: 587 | C22: 46042 | D22: 3 | E22: 3612 | F22: 0 | G22: 0 | H22: 3 | I22: 3612
C23: 46043
C24: 46044
C25: 46045
A26: 46045 | B26: 588 | C26: 46046 | D26: 5 | E26: 5446 | F26: 0 | G26: 0 | H26: 5 | I26: 5446
C27: 46047
A28: 46045 | B28: 588 | C28: 46048 | D28: 25 | E28: 25265 | F28: 0 | G28: 0 | H28: 25 | I28: 25265
A29: 46045 | B29: 588 | C29: 46049 | D29: 6 | E29: 5624 | F29: 0 | G29: 0 | H29: 6 | I29: 5624
A30: 46045 | B30: 588 | C30: 46050 | D30: 8 | E30: 4797 | F30: 0 | G30: 0 | H30: 8 | I30: 4797
A31: 46045 | B31: 588 | C31: 46051 | D31: 2 | E31: 1855 | F31: 0 | G31: 0 | H31: 2 | I31: 1855
A32: 46050 | B32: 591 | C32: 46052 | D32: 10 | E32: 10650 | F32: 0 | G32: 0 | H32: 10 | I32: 10650
A33: 46050 | B33: 591 | C33: 46053 | D33: 21 | E33: 20005 | F33: 0 | G33: 0 | H33: 21 | I33: 20005

Sheet MED
D1: =D3+D4+D5+D6+D7+D8+D9+D10+D11+D12+D13+D14+D15+D16+D17+D18+D19+D20+D21+D22+D23+D24+D25+D26+D27+D28+D29+D30+D31+D32+D33 -> 54 | E1: =E3+E4+E5+E6+E7+E8+E9+E10+E11+E12+E13+E14+E15+E16+E17+E18+E19+E20+E21+E22+E23+E24+E25+E26+E27+E28+E29+E30+E31+E32+E33 -> 48188.75 | F1: =F3+F4+F5+F6+F7+F8+F9+F10+F11+F12+F13+F14+F15+F16+F17+F18+F19+F20+F21+F22+F23+F24+F25+F26+F27+F28+F29+F30+F31+F32+F33 -> 0 | G1: =G3+G4+G5+G6+G7+G8+G9+G10+G11+G12+G13+G14+G15+G16+G17+G18+G19+G20+G21+G22+G23+G24+G25+G26+G27+G28+G29+G30+G31+G32+G33 -> 0 | H1: =H3+H4+H5+H6+H7+H8+H9+H10+H11+H12+H13+H14+H15+H16+H17+H18+H19+H20+H21+H22+H23+H24+H25+H26+H27+H28+H29+H30+H31+H32+H33 -> 54 | I1: =I3+I4+I5+I6+I7+I8+I9+I10+I11+I12+I13+I14+I15+I16+I17+I18+I19+I20+I21+I22+I23+I24+I25+I26+I27+I28+I29+I30+I31+I32+I33 -> 48188.75
A2: Import Date | B2: Batch Number | C2: Strike Date | D2: Received Volume | E2: Received Value | F2: Rejected Volume | G2: Rejected Value | H2: Accepted Volume | I2: Accepted Value
C3: 46023
A4: 46748 | B4: 538&539 | C4: 46024 | D4: 18 | E4: 18466 | F4: 0 | G4: 0 | H4: 18 | I4: 18466
C5: 46025
C6: 46026
A7: 46021 | B7: 539 | C7: 46027 | D7: 3 | E7: 1555 | F7: 0 | G7: 0 | H7: 3 | I7: 1555
C8: 46028
A9: 1//2 | B9: 540 | C9: 46029 | D9: 1 | E9: 935 | F9: 0 | G9: 0 | H9: 1 | I9: 935
C10: 46030
C11: 46031
C12: 46032
C13: 46033
A14: 46028 | B14: 541 | C14: 46034 | D14: 1 | E14: 875 | F14: 0 | G14: 0 | H14: 1 | I14: 875
C15: 46035
C16: 46036
A17: 46031 | B17: 542 | C17: 46037 | D17: 2 | E17: 1638 | F17: 0 | G17: 0 | H17: 2 | I17: 1638
C18: 46038
C19: 46039
C20: 46040
C21: 46041
A22: 46041 | B22: 543 | C22: 46042 | D22: 2 | E22: 1230 | F22: 0 | G22: 0 | H22: 2 | I22: 1230
C23: 46043
C24: 46044
C25: 46045
A26: 46045 | B26: 544 | C26: 46046 | D26: 2 | E26: 1300 | F26: 0 | G26: 0 | H26: 2 | I26: 1300
C27: 46047
A28: 46045 | B28: 544 | C28: 46048 | D28: 13 | E28: 11883 | F28: 0 | G28: 0 | H28: 13 | I28: 11883
A29: 46045 | B29: 544 | C29: 46049 | D29: 3 | E29: 2461 | F29: 0 | G29: 0 | H29: 3 | I29: 2461
A30: 46045 | B30: 544 | C30: 46050 | D30: 1 | E30: 918.75 | F30: 0 | G30: 0 | H30: 1 | I30: 918.75
C31: 46051
A32: 46050 | B32: 547 | C32: 46052 | D32: 3 | E32: 2592 | F32: 0 | G32: 0 | H32: 3 | I32: 2592
A33: 46050 | B33: 547 | C33: 46053 | D33: 5 | E33: 4335 | F33: 0 | G33: 0 | H33: 5 | I33: 4335

Sheet MEM
D1: =D3+D4+D5+D6+D7+D8+D9+D10+D11+D12+D13+D14+D15+D16+D17+D18+D19+D20+D21+D22+D23+D24+D25+D26+D27+D28+D29+D30+D31+D32+D33 -> 56 | E1: =E3+E4+E5+E6+E7+E8+E9+E10+E11+E12+E13+E14+E15+E16+E17+E18+E19+E20+E21+E22+E23+E24+E25+E26+E27+E28+E29+E30+E31+E32+E33 -> 52231 | F1: =F3+F4+F5+F6+F7+F8+F9+F10+F11+F12+F13+F14+F15+F16+F17+F18+F19+F20+F21+F22+F23+F24+F25+F26+F27+F28+F29+F30+F31+F32+F33 -> 0 | G1: =G3+G4+G5+G6+G7+G8+G9+G10+G11+G12+G13+G14+G15+G16+G17+G18+G19+G20+G21+G22+G23+G24+G25+G26+G27+G28+G29+G30+G31+G32+G33 -> 0 | H1: =H3+H4+H5+H6+H7+H8+H9+H10+H11+H12+H13+H14+H15+H16+H17+H18+H19+H20+H21+H22+H23+H24+H25+H26+H27+H28+H29+H30+H31+H32+H33 -> 56 | I1: =I3+I4+I5+I6+I7+I8+I9+I10+I11+I12+I13+I14+I15+I16+I17+I18+I19+I20+I21+I22+I23+I24+I25+I26+I27+I28+I29+I30+I31+I32+I33 -> 52231
A2: Import Date | B2: Batch Number | C2: Strike Date | D2: Received Volume | E2: Received Value | F2: Rejected Volume | G2: Rejected Value | H2: Accepted Volume | I2: Accepted Value
C3: 46023
A4: 46018 | B4: 536&537 | C4: 46024 | D4: 17 | E4: 15514 | F4: 0 | G4: 0 | H4: 17 | I4: 15514
A5: 46021 | B5: 537 | C5: 46025 | D5: 2 | E5: 1330 | F5: 0 | G5: 0 | H5: 2 | I5: 1330
C6: 46026
A7: 46021 | B7: 537 | C7: 46027 | D7: 3 | E7: 2235 | F7: 0 | G7: 0 | H7: 3 | I7: 2235
A8: 46024 | B8: 538 | C8: 46028 | D8: 1 | E8: 791 | F8: 0 | G8: 0 | H8: 1 | I8: 791
A9: 46024 | B9: 538 | C9: 46029 | D9: 1 | E9: 2195 | F9: 0 | G9: 0 | H9: 1 | I9: 2195
C10: 46030
C11: 46031
A12: 46028 | B12: 539 | C12: 46032 | D12: 2 | E12: 1090 | F12: 0 | G12: 0 | H12: 2 | I12: 1090
C13: 46033
C14: 46034
C15: 46035
A16: 46031 | B16: 540 | C16: 46036 | D16: 2 | E16: 1656 | F16: 0 | G16: 0 | H16: 2 | I16: 1656
A17: 46031 | B17: 540 | C17: 46037 | D17: 3 | E17: 2261 | F17: 0 | G17: 0 | H17: 3 | I17: 2261
C18: 46038
C19: 46039
C20: 46040
C21: 46041
A22: 46041 | B22: 541 | C22: 46042 | D22: 4 | E22: 3934 | F22: 0 | G22: 0 | H22: 4 | I22: 3934
A23: 46041 | B23: 541 | C23: 46043 | D23: 1 | E23: 791 | F23: 0 | G23: 0 | H23: 1 | I23: 791
C24: 46044
C25: 46045
A26: 46045 | B26: 542 | C26: 46046 | D26: 5 | E26: 6214 | F26: 0 | G26: 0 | H26: 5 | I26: 6214
C27: 46047
A28: 46045 | B28: 542 | C28: 46048 | D28: 11 | E28: 9211 | F28: 0 | G28: 0 | H28: 11 | I28: 9211
C29: 46049
C30: 46050
C31: 46051
C32: 46052
A33: 46050 | B33: 543 | C33: 46053 | D33: 4 | E33: 5009 | F33: 0 | G33: 0 | H33: 4 | I33: 5009

Sheet MKT
D1: =D3+D4+D5+D6+D7+D8+D9+D10+D11+D12+D13+D14+D15+D16+D17+D18+D19+D20+D21+D22+D23+D24+D25+D26+D27+D28+D29+D30+D31+D32+D33 -> 17 | E1: =E3+E4+E5+E6+E7+E8+E9+E10+E11+E12+E13+E14+E15+E16+E17+E18+E19+E20+E21+E22+E23+E24+E25+E26+E27+E28+E29+E30+E31+E32+E33 -> 16844.75 | F1: =F3+F4+F5+F6+F7+F8+F9+F10+F11+F12+F13+F14+F15+F16+F17+F18+F19+F20+F21+F22+F23+F24+F25+F26+F27+F28+F29+F30+F31+F32+F33 -> 0 | G1: =G3+G4+G5+G6+G7+G8+G9+G10+G11+G12+G13+G14+G15+G16+G17+G18+G19+G20+G21+G22+G23+G24+G25+G26+G27+G28+G29+G30+G31+G32+G33 -> 0 | H1: =H3+H4+H5+H6+H7+H8+H9+H10+H11+H12+H13+H14+H15+H16+H17+H18+H19+H20+H21+H22+H23+H24+H25+H26+H27+H28+H29+H30+H31+H32+H33 -> 17 | I1: =I3+I4+I5+I6+I7+I8+I9+I10+I11+I12+I13+I14+I15+I16+I17+I18+I19+I20+I21+I22+I23+I24+I25+I26+I27+I28+I29+I30+I31+I32+I33 -> 16844.75
A2: Import Date | B2: Batch Number | C2: Strike Date | D2: Received Volume | E2: Received Value | F2: Rejected Volume | G2: Rejected Value | H2: Accepted Volume | I2: Accepted Value
C3: 46023
A4: 46018 | B4: 431 | C4: 46024 | D4: 7 | E4: 6926 | F4: 0 | G4: 0 | H4: 7 | I4: 6926
A5: 46021 | B5: 432 | C5: 46025 | D5: 1 | E5: 875 | F5: 0 | G5: 0 | H5: 1 | I5: 875
C6: 46026
C7: 46027
C8: 46028
C9: 46029
C10: 46030
C11: 46031
C12: 46032
C13: 46033
C14: 46034
C15: 46035
A16: 46031 | B16: 433 | C16: 46036 | D16: 2 | E16: 2310 | F16: 0 | G16: 0 | H16: 2 | I16: 2310
A17: 46031 | B17: 433 | C17: 46037 | D17: 2 | E17: 2072 | F17: 0 | G17: 0 | H17: 2 | I17: 2072
C18: 46038
C19: 46039
C20: 46040
C21: 46041
C22: 46042
C23: 46043
C24: 46044
C25: 46045
C26: 46046
C27: 46047
C28: 46048
C29: 46049
A30: 46045 | B30: 434 | C30: 46050 | D30: 2 | E30: 1860 | F30: 0 | G30: 0 | H30: 2 | I30: 1860
C31: 46051
A32: 46050 | B32: 435 | C32: 46052 | D32: 1 | E32: 918.75 | F32: 0 | G32: 0 | H32: 1 | I32: 918.75
A33: 46050 | B33: 435 | C33: 46053 | D33: 2 | E33: 1883 | F33: 0 | G33: 0 | H33: 2 | I33: 1883

Sheet MTS
D1: =D3+D4+D5+D6+D7+D8+D9+D10+D11+D12+D13+D14+D15+D16+D17+D18+D19+D20+D21+D22+D23+D24+D25+D26+D27+D28+D29+D30+D31+TFG!D32+D33 -> 6 | E1: =E3+E4+E5+E6+E7+E8+E9+E10+E11+E12+E13+E14+E15+E16+E17+E18+E19+E20+E21+E22+E23+E24+E25+E26+E27+E28+E29+E30+E31+TFG!E32+E33 -> 3729 | F1: =F3+F4+F5+F6+F7+F8+F9+F10+F11+F12+F13+F14+F15+F16+F17+F18+F19+F20+F21+F22+F23+F24+F25+F26+F27+F28+F29+F30+F31+TFG!F32+F33 -> 0 | G1: =G3+G4+G5+G6+G7+G8+G9+G10+G11+G12+G13+G14+G15+G16+G17+G18+G19+G20+G21+G22+G23+G24+G25+G26+G27+G28+G29+G30+G31+TFG!G32+G33 -> 0 | H1: =H3+H4+H5+H6+H7+H8+H9+H10+H11+H12+H13+H14+H15+H16+H17+H18+H19+H20+H21+H22+H23+H24+H25+H26+H27+H28+H29+H30+H31+TFG!H32+H33 -> 6 | I1: =I3+I4+I5+I6+I7+I8+I9+I10+I11+I12+I13+I14+I15+I16+I17+I18+I19+I20+I21+I22+I23+I24+I25+I26+I27+I28+I29+I30+I31+TFG!I32+I33 -> 3729
A2: Import Date | B2: Batch Number | C2: Strike Date | D2: Received Volume | E2: Received Value | F2: Rejected Volume | G2: Rejected Value | H2: Accepted Volume | I2: Accepted Value
C3: 46023
C4: 46024
C5: 46025
C6: 46026
C7: 46027
C8: 46028
A9: 46024 | B9: 306 | C9: 46029 | D9: 2 | E9: 1143 | F9: 0 | G9: 0 | H9: 2 | I9: 1143
C10: 46030
C11: 46031
C12: 46032
C13: 46033
C14: 46034
C15: 46035
C16: 46036
C17: 46037
C18: 46038
C19: 46039
C20: 46040
C21: 46041
... C28: 46048
A29: 46045 | B29: 307 | C29: 46049 | D29: 1 | E29: 665 | F29: 0 | G29: 0 | H29: 1 | I29: 665
A30: 46045 | B30: 307 | C30: 46050 | D30: 1 | E30: 931 | F30: 0 | G30: 0 | H30: 1 | I30: 931
A31: 46045 | B31: 307 | C31: 46051 | D31: 1 | E31: 665 | F31: 0 | G31: 0 | H31: 1 | I31: 665
C32: 46052
C33: 46053

Sheet NAV
D1: =D3+D4+D5+D6+D7+D8+D9+D10+D11+D12+D13+D14+D15+D16+D17+D18+D19+D20+D21+D22+D23+D24+D25+D26+D27+D28+D29+D30+D31+D32+D33 -> 36 | E1: =E3+E4+E5+E6+E7+E8+E9+E10+E11+E12+E13+E14+E15+E16+E17+E18+E19+E20+E21+E22+E23+E24+E25+E26+E27+E28+E29+E30+E31+E32+E33 -> 14944 | F1: =F3+F4+F5+F6+F7+F8+F9+F10+F11+F12+F13+F14+F15+F16+F17+F18+F19+F20+F21+F22+F23+F24+F25+F26+F27+F28+F29+F30+F31+F32+F33 -> 0 | G1: =G3+G4+G5+G6+G7+G8+G9+G10+G11+G12+G13+G14+G15+G16+G17+G18+G19+G20+G21+G22+G23+G24+G25+G26+G27+G28+G29+G30+G31+G32+G33 -> 0 | H1: =H3+H4+H5+H6+H7+H8+H9+H10+H11+H12+H13+H14+H15+H16+H17+H18+H19+H20+H21+H22+H23+H24+H25+H26+H27+H28+H29+H30+H31+H32+H33 -> 36 | I1: =I3+I4+I5+I6+I7+I8+I9+I10+I11+I12+I13+I14+I15+I16+I17+I18+I19+I20+I21+I22+I23+I24+I25+I26+I27+I28+I29+I30+I31+I32+I33 -> 14944
A2: Import Date | B2: Batch Number | C2: Strike Date | D2: Received Volume | E2: Received Value | F2: Rejected Volume | G2: Rejected Value | H2: Accepted Volume | I2: Accepted Value
C3: 46023
A4: 46021 | B4: 434 | C4: 46024 | D4: 9 | E4: 3596 | F4: 0 | G4: 0 | H4: 9 | I4: 3596
C5: 46025
C6: 46026
A7: 46021 | B7: 434 | C7: 46027 | D7: 2 | E7: 650 | F7: 0 | G7: 0 | H7: 2 | I7: 650
A8: 46024 | B8: 435 | C8: 46028 | D8: 1 | E8: 385 | F8: 0 | G8: 0 | H8: 1 | I8: 385
A9: 46024 | B9: 435 | C9: 46029 | D9: 3 | E9: 1035 | F9: 0 | G9: 0 | H9: 3 | I9: 1035
C10: 46030
C11: 46031
C12: 46032
C13: 46033
C14: 46034
C15: 46035
C16: 46036
A17: 46031 | B17: 436 | C17: 46037 | D17: 1 | E17: 325 | F17: 0 | G17: 0 | H17: 1 | I17: 325
C18: 46038
C19: 46039
C20: 46040
C21: 46041
C22: 46042
C23: 46043
C24: 46044
C25: 46045
A26: 46045 | B26: 438 | C26: 46046 | D26: 1 | E26: 385 | F26: 0 | G26: 0 | H26: 1 | I26: 385
C27: 46047
A28: 46045 | B28: 438 | C28: 46048 | D28: 4 | E28: 2234 | F28: 0 | G28: 0 | H28: 4 | I28: 2234
A29: 46045 | B29: 438 | C29: 46049 | D29: 6 | E29: 3111 | F29: 0 | G29: 0 | H29: 6 | I29: 3111
A30: 46045 | B30: 438 | C30: 46050 | D30: 3 | E30: 975 | F30: 0 | G30: 0 | H30: 3 | I30: 975
C31: 46051
A32: 46050 | B32: 441 | C32: 46052 | D32: 3 | E32: 890 | F32: 0 | G32: 0 | H32: 3 | I32: 890
A33: 46050 | B33: 441 | C33: 46053 | D33: 3 | E33: 1358 | F33: 0 | G33: 0 | H33: 3 | I33: 1358

Sheet NUM{THR}
D1: =D3+D4+D5+D6+D7+D8+D9+D10+D11+D12+D13+D14+D15+D16+D17+D18+D19+D20+D21+D22+D23+D24+D25+D26+D27+D28+D29+D30+D31+D32+D33 -> 1 | E1: =E3+E4+E5+E6+E7+E8+E9+E10+E11+E12+E13+E14+E15+E16+E17+E18+E19+E20+E21+E22+E23+E24+E25+E26+E27+E28+E29+E30+E31+E32+E33 -> 665 | F1: =F3+F4+F5+F6+F7+F8+F9+F10+F11+F12+F13+F14+F15+F16+F17+F18+F19+F20+F21+F22+F23+F24+F25+F26+F27+F28+F29+F30+F31+F32+F33 -> 0 | G1: =G3+G4+G5+G6+G7+G8+G9+G10+G11+G12+G13+G14+G15+G16+G17+G18+G19+G20+G21+G22+G23+G24+G25+G26+G27+G28+G29+G30+G31+G32+G33 -> 0 | H1: =H3+H4+H5+H6+H7+H8+H9+H10+H11+H12+H13+H14+H15+H16+H17+H18+H19+H20+H21+H22+H23+H24+H25+H26+H27+H28+H29+H30+H31+H32+H33 -> 1 | I1: =I3+I4+I5+I6+I7+I8+I9+I10+I11+I12+I13+I14+I15+I16+I17+I18+I19+I20+I21+I22+I23+I24+I25+I26+I27+I28+I29+I30+I31+I32+I33 -> 665
A2: Import Date | B2: Batch Number | C2: Strike Date | D2: Received Volume | E2: Received Value | F2: Rejected Volume | G2: Rejected Value | H2: Accepted Volume | I2: Accepted Value
A3: 45988 | B3: 60 | C3: 46023
C4: 46024
C5: 46025
C6: 46026
C7: 46027
C8: 46028
C9: 46029
C10: 46030
C11: 46031
C12: 46032
C13: 46033
C14: 46034
C15: 46035
... C31: 46051
A32: 46050 | B32: 62 | C32: 46052 | D32: 1 | E32: 665 | F32: 0 | G32: 0 | H32: 1 | I32: 665
C33: 46053

Sheet PAR
D1: =D3+D4+D5+D6+D7+D8+D9+D10+D11+D12+D13+D14+D15+D16+D17+D18+D19+D20+D21+D22+D23+D24+D25+D26+D27+D28+D31+D32+D33+D29+D30 -> 716 | E1: =E3+E4+E5+E6+E7+E8+E9+E10+E11+E12+E13+E14+E15+E16+E17+E18+E19+E20+E21+E22+E23+E24+E25+E26+E27+E28+E31+E32+E33+E29+E30 -> 738011.5 | F1: =F3+F4+F5+F6+F7+F8+F9+F10+F11+F12+F13+F14+F15+F16+F17+F18+F19+F20+F21+F22+F23+F24+F25+F26+F27+F28+F31+F32+F33+F29+F30 -> 0 | G1: =G3+G4+G5+G6+G7+G8+G9+G10+G11+G12+G13+G14+G15+G16+G17+G18+G19+G20+G21+G22+G23+G24+G25+G26+G27+G28+G31+G32+G33+G29+G30 -> 0 | H1: =H3+H4+H5+H6+H7+H8+H9+H10+H11+H12+H13+H14+H15+H16+H17+H18+H19+H20+H21+H22+H23+H24+H25+H26+H27+H28+H31+H32+H33+H29+H30 -> 716 | I1: =I3+I4+I5+I6+I7+I8+I9+I10+I11+I12+I13+I14+I15+I16+I17+I18+I19+I20+I21+I22+I23+I24+I25+I26+I27+I28+I31+I32+I33+I29+I30 -> 738011.5
A2: Import Date | B2: Batch Number | C2: Strike Date | D2: Received Volume | E2: Received Value | F2: Rejected Volume | G2: Rejected Value | H2: Accepted Volume | I2: Accepted Value
C3: 46023
A4: 46018 | B4: 583&584 | C4: 46024 | D4: 276 | E4: 288531.5 | F4: 0 | G4: 0 | H4: 276 | I4: 288531.5
A5: 46021 | B5: 584 | C5: 46025 | D5: 29 | E5: 32278 | F5: 0 | G5: 0 | H5: 29 | I5: 32278
C6: 46026
A7: 46021 | B7: 584 | C7: 46027 | D7: 25 | E7: 22746 | F7: 0 | G7: 0 | H7: 25 | I7: 22746
A8: 46024 | B8: 585 | C8: 46028 | D8: 7 | E8: 6581 | F8: 0 | G8: 0 | H8: 7 | I8: 6581
A9: 46024 | B9: 585 | C9: 46029 | D9: 55 | E9: 53667 | F9: 0 | G9: 0 | H9: 55 | I9: 53667
A10: 46024 | B10: 585 | C10: 46030 | D10: 2 | E10: 965 | F10: 0 | G10: 0 | H10: 2 | I10: 965
A11: 46028 | B11: 586 | C11: 46031 | D11: 1 | E11: 985 | F11: 0 | G11: 0 | H11: 1 | I11: 985
A12: 46028 | B12: 586 | C12: 46032 | D12: 3 | E12: 3251 | F12: 0 | G12: 0 | H12: 3 | I12: 3251
C13: 46033
A14: 46028 | B14: 586 | C14: 46034 | D14: 3 | E14: 2671 | F14: 0 | G14: 0 | H14: 3 | I14: 2671
C15: 46035
A16: 46031 | B16: 587 | C16: 46036 | D16: 10 | E16: 8894 | F16: 0 | G16: 0 | H16: 10 | I16: 8894
A17: 46031 | B17: 587 | C17: 46037 | D17: 23 | E17: 27454 | F17: 0 | G17: 0 | H17: 23 | I17: 27454
A18: 46035 | B18: 588 | C18: 46038 | D18: 4 | E18: 4821 | F18: 0 | G18: 0 | H18: 4 | I18: 4821
A19: 46035 | B19: 588 | C19: 46039 | D19: 2 | E19: 1650 | F19: 0 | G19: 0 | H19: 2 | I19: 1650
C20: 46040
C21: 46041
A22: 46041 | B22: 589 | C22: 46042 | D22: 5 | E22: 3821 | F22: 0 | G22: 0 | H22: 5 | I22: 3821
A23: 46041 | B23: 589 | C23: 46043 | D23: 6 | E23: 5238 | F23: 0 | G23: 0 | H23: 6 | I23: 5238
A24: 46041 | B24: 589 | C24: 46044 | D24: 2 | E24: 1540 | F24: 0 | G24: 0 | H24: 2 | I24: 1540
C25: 46045
A26: 46045 | B26: 590 | C26: 46046 | D26: 18 | E26: 17370 | F26: 0 | G26: 0 | H26: 18 | I26: 17370
C27: 46047
A28: 46045 | B28: 590 | C28: 46048 | D28: 87 | E28: 93044 | F28: 0 | G28: 0 | H28: 87 | I28: 93044
A29: 46045 | B29: 590 | C29: 46049 | D29: 20 | E29: 21578 | F29: 0 | G29: 0 | H29: 20 | I29: 21578
A30: 46045 | B30: 590 | C30: 46050 | D30: 23 | E30: 21821 | F30: 0 | G30: 0 | H30: 23 | I30: 21821
A31: 46045 | B31: 590 | C31: 46051 | D31: 5 | E31: 5177 | F31: 0 | G31: 0 | H31: 5 | I31: 5177
A32: 46050 | B32: 591 | C32: 46052 | D32: 42 | E32: 39069 | F32: 0 | G32: 0 | H32: 42 | I32: 39069
A33: 46050 | B33: 591 | C33: 46053 | D33: 68 | E33: 74859 | F33: 0 | G33: 0 | H33: 68 | I33: 74859

Sheet RAN
D1: =D3+D4+D5+D6+D7+D8+D9+D10+D11+D12+D13+D14+D15+D16+D17+D18+D19+D20+D21+D22+D23+D24+D25+D26+D27+D28+D29+D30+D31+D32+D33 -> 0 | E1: =E3+E4+E5+E6+E7+E8+E9+E10+E11+E12+E13+E14+E15+E16+E17+E18+E19+E20+E21+E22+E23+E24+E25+E26+E27+E28+E29+E30+E31+E32+E33 -> 0 | F1: =F3+F4+F5+F6+F7+F8+F9+F10+F11+F12+F13+F14+F15+F16+F17+F18+F19+F20+F21+F22+F23+F24+F25+F26+F27+F28+F29+F30+F31+F32+F33 -> 0 | G1: =G3+G4+G5+G6+G7+G8+G9+G10+G11+G12+G13+G14+G15+G16+G17+G18+G19+G20+G21+G22+G23+G24+G25+G26+G27+G28+G29+G30+G31+G32+G33 -> 0 | H1: =H3+H4+H5+H6+H7+H8+H9+H10+H11+H12+H13+H14+H15+H16+H17+H18+H19+H20+H21+H22+H23+H24+H25+H26+H27+H28+H29+H30+H31+H32+H33 -> 0 | I1: =I3+I4+I5+I6+I7+I8+I9+I10+I11+I12+I13+I14+I15+I16+I17+I18+I19+I20+I21+I22+I23+I24+I25+I26+I27+I28+I29+I30+I31+I32+I33 -> 0
A2: Import Date | B2: Batch Number | C2: Strike Date | D2: Received Volume | E2: Received Value | F2: Rejected Volume | G2: Rejected Value | H2: Accepted Volume | I2: Accepted Value
A3: 45868 | B3: 76 | C3: 46023
C4: 46024
C5: 46025
C6: 46026
C7: 46027
C8: 46028
C9: 46029
C10: 46030
C11: 46031
C12: 46032
C13: 46033
C14: 46034
C15: 46035
... C20: 46040
A21: 45884 | B21: 77 | C21: 46041
C22: 46042
C23: 46043
C24: 46044
C25: 46045
C26: 46046
C27: 46047
C28: 46048
C29: 46049
C30: 46050
C31: 46051
C32: 46052
C33: 46053

Sheet RCO
D1: =D3+D4+D5+D6+D7+D8+D9+D10+D11+D12+D13+D14+D15+D16+D17+D18+D19+D20+D21+D22+D23+D24+D25+D26+D27+D28+D29+D30+D31+D32+D33 -> 1 | E1: =E3+E4+E5+E6+E7+E8+E9+E10+E11+E12+E13+E14+E15+E16+E17+E18+E19+E20+E21+E22+E23+E24+E25+E26+E27+E28+E29+E30+E31+E32+E33 -> 665 | F1: =F3+F4+F5+F6+F7+F8+F9+F10+F11+F12+F13+F14+F15+F16+F17+F18+F19+F20+F21+F22+F23+F24+F25+F26+F27+F28+F29+F30+F31+F32+F33 -> 0 | G1: =G3+G4+G5+G6+G7+G8+G9+G10+G11+G12+G13+G14+G15+G16+G17+G18+G19+G20+G21+G22+G23+G24+G25+G26+G27+G28+G29+G30+G31+G32+G33 -> 0 | H1: =H3+H4+H5+H6+H7+H8+H9+H10+H11+H12+H13+H14+H15+H16+H17+H18+H19+H20+H21+H22+H23+H24+H25+H26+H27+H28+H29+H30+H31+H32+H33 -> 1 | I1: =I3+I4+I5+I6+I7+I8+I9+I10+I11+I12+I13+I14+I15+I16+I17+I18+I19+I20+I21+I22+I23+I24+I25+I26+I27+I28+I29+I30+I31+I32+I33 -> 665
A2: Import Date | B2: Batch Number | C2: Strike Date | D2: Received Volume | E2: Received Value | F2: Rejected Volume | G2: Rejected Value | H2: Accepted Volume | I2: Accepted Value
C3: 46023
A4: 46018 | B4: 207 | C4: 46024 | D4: 1 | E4: 665 | F4: 0 | G4: 0 | H4: 1 | I4: 665
C5: 46025
C6: 46026
C7: 46027
C8: 46028
C9: 46029
C10: 46030
C11: 46031
C12: 46032
C13: 46033
C14: 46034
C15: 46035
C16: 46036
... C33: 46053

Sheet SA
D1: =D3+D4+D5+D6+D7+D8+D9+D10+D11+D12+D13+D14+D15+D16+D17+D18+D19+D20+D21+D22+D23+D24+D25+D26+D27+D28+D29+D30+D31+D32+D33 -> 892 | E1: =E3+E4+E5+E6+E7+E8+E9+E10+E11+E12+E13+E14+E15+E16+E17+E18+E19+E20+E21+E22+E23+E24+E25+E26+E27+E28+E29+E30+E31+E32+E33 -> 959816.5 | F1: =F3+F4+F5+F6+F7+F8+F9+F10+F11+F12+F13+F14+F15+F16+F17+F18+F19+F20+F21+F22+F23+F24+F25+F26+F27+F28+F29+F30+F31+F32+F33 -> 0 | G1: =G3+G4+G5+G6+G7+G8+G9+G10+G11+G12+G13+G14+G15+G16+G17+G18+G19+G20+G21+G22+G23+G24+G25+G26+G27+G28+G29+G30+G31+G32+G33 -> 0 | H1: =H3+H4+H5+H6+H7+H8+H9+H10+H11+H12+H13+H14+H15+H16+H17+H18+H19+H20+H21+H22+H23+H24+H25+H26+H27+H28+H29+H30+H31+H32+H33 -> 892 | I1: =I3+I4+I5+I6+I7+I8+I9+I10+I11+I12+I13+I14+I15+I16+I17+I18+I19+I20+I21+I22+I23+I24+I25+I26+I27+I28+I29+I30+I31+I32+I33 -> 959816.5
A2: Import Date | B2: Batch Number | C2: Strike Date | D2: Received Volume | E2: Received Value | F2: Rejected Volume | G2: Rejected Value | H2: Accepted Volume | I2: Accepted Value
C3: 46023
A4: 46018 | B4: 592&593 | C4: 46024 | D4: 292 | E4: 313331.75 | F4: 0 | G4: 0 | H4: 292 | I4: 313331.75
A5: 46021 | B5: 593 | C5: 46025 | D5: 19 | E5: 22109 | F5: 0 | G5: 0 | H5: 19 | I5: 22109
C6: 46026
A7: 46021 | B7: 593 | C7: 46027 | D7: 37 | E7: 43742 | F7: 0 | G7: 0 | H7: 37 | I7: 43742
A8: 46024 | B8: 594 | C8: 46028 | D8: 6 | E8: 6578 | F8: 0 | G8: 0 | H8: 6 | I8: 6578
A9: 46024 | B9: 594 | C9: 46029 | D9: 29 | E9: 35766 | F9: 0 | G9: 0 | H9: 29 | I9: 35766
A10: 46024 | B10: 594 | C10: 46030 | D10: 3 | E10: 3446 | F10: 0 | G10: 0 | H10: 3 | I10: 3446
C11: 46031
A12: 46028 | B12: 595 | C12: 46032 | D12: 6 | E12: 6937 | F12: 0 | G12: 0 | H12: 6 | I12: 6937
C13: 46033
A14: 46028 | B14: 595 | C14: 46034 | D14: 2 | E14: 1560 | F14: 0 | G14: 0 | H14: 2 | I14: 1560
C15: 46035
A16: 46031 | B16: 596 | C16: 46036 | D16: 23 | E16: 24491 | F16: 0 | G16: 0 | H16: 23 | I16: 24491
A17: 46031 | B17: 596 | C17: 46037 | D17: 29 | E17: 24920 | F17: 0 | G17: 0 | H17: 29 | I17: 24920
A18: 46035 | B18: 597 | C18: 46038 | D18: 3 | E18: 4044 | F18: 0 | G18: 0 | H18: 3 | I18: 4044
A19: 46035 | B19: 597 | C19: 46039 | D19: 7 | E19: 11785 | F19: 0 | G19: 0 | H19: 7 | I19: 11785
C20: 46040
C21: 46041
A22: 46041 | B22: 598 | C22: 46042 | D22: 11 | E22: 12974 | F22: 0 | G22: 0 | H22: 11 | I22: 12974
A23: 46041 | B23: 598 | C23: 46043 | D23: 3 | E23: 3557 | F23: 0 | G23: 0 | H23: 3 | I23: 3557
C24: 46044
C25: 46045
A26: 46045 | B26: 599 | C26: 46046 | D26: 29 | E26: 36541 | F26: 0 | G26: 0 | H26: 29 | I26: 36541
C27: 46047
A28: 46045 | B28: 599 | C28: 46048 | D28: 143 | E28: 159576 | F28: 0 | G28: 0 | H28: 143 | I28: 159576
A29: 46045 | B29: 599 | C29: 46049 | D29: 35 | E29: 29716 | F29: 0 | G29: 0 | H29: 35 | I29: 29716
A30: 46045 | B30: 599 | C30: 46050 | D30: 63 | E30: 57179 | F30: 0 | G30: 0 | H30: 63 | I30: 57179
A31: 46045 | B31: 599 | C31: 46051 | D31: 12 | E31: 11770 | F31: 0 | G31: 0 | H31: 12 | I31: 11770
A32: 46050 | B32: 600 | C32: 46052 | D32: 56 | E32: 56392.75 | F32: 0 | G32: 0 | H32: 56 | I32: 56392.75
